INFO 2022-04-28 19:05:53,746 basehttp 4216 4940 "GET /products/ HTTP/1.1" 200 11817
INFO 2022-04-28 19:05:53,923 basehttp 4216 4940 "GET /favicon.ico HTTP/1.1" 200 66
INFO 2022-04-28 19:05:59,639 log 4216 4940 OK: /products/
Traceback (most recent call last):
  File "C:\Python310\lib\site-packages\rest_framework\serializers.py", line 962, in create
    instance = ModelClass._default_manager.create(**validated_data)
  File "C:\Python310\lib\site-packages\django\db\models\manager.py", line 85, in manager_method
    return getattr(self.get_queryset(), name)(*args, **kwargs)
  File "C:\Python310\lib\site-packages\django\db\models\query.py", line 512, in create
    obj = self.model(**kwargs)
  File "C:\Python310\lib\site-packages\django\db\models\base.py", line 559, in __init__
    raise TypeError(
TypeError: Product() got an unexpected keyword argument 'owner'

During handling of the above exception, another exception occurred:

Traceback (most recent call last):
  File "C:\Python310\lib\site-packages\django\core\handlers\exception.py", line 55, in inner
    response = get_response(request)
  File "C:\Python310\lib\site-packages\django\core\handlers\base.py", line 197, in _get_response
    response = wrapped_callback(request, *callback_args, **callback_kwargs)
  File "C:\Python310\lib\site-packages\django\views\decorators\csrf.py", line 54, in wrapped_view
    return view_func(*args, **kwargs)
  File "C:\Python310\lib\site-packages\rest_framework\viewsets.py", line 125, in view
    return self.dispatch(request, *args, **kwargs)
  File "C:\Python310\lib\site-packages\rest_framework\views.py", line 509, in dispatch
    response = self.handle_exception(exc)
  File "C:\Python310\lib\site-packages\rest_framework\views.py", line 469, in handle_exception
    self.raise_uncaught_exception(exc)
  File "C:\Python310\lib\site-packages\rest_framework\views.py", line 480, in raise_uncaught_exception
    raise exc
  File "C:\Python310\lib\site-packages\rest_framework\views.py", line 506, in dispatch
    response = handler(request, *args, **kwargs)
  File "C:\Python310\lib\site-packages\rest_framework\mixins.py", line 19, in create
    self.perform_create(serializer)
  File "C:\Users\Lenovo\Documents\projects\InventoryManagementSystem\inventorymanagementsystem\apps\products\views.py", line 43, in perform_create
    serializer.save(owner=self.request.user)
  File "C:\Python310\lib\site-packages\rest_framework\serializers.py", line 212, in save
    self.instance = self.create(validated_data)
  File "C:\Python310\lib\site-packages\rest_framework\serializers.py", line 981, in create
    raise TypeError(msg)
TypeError: Got a `TypeError` when calling `Product.objects.create()`. This may be because you have a writable field on the serializer class that is not a valid argument to `Product.objects.create()`. You may need to make the field read-only, or override the ProductSerializer.create() method to handle this correctly.
Original exception was:
 Traceback (most recent call last):
  File "C:\Python310\lib\site-packages\rest_framework\serializers.py", line 962, in create
    instance = ModelClass._default_manager.create(**validated_data)
  File "C:\Python310\lib\site-packages\django\db\models\manager.py", line 85, in manager_method
    return getattr(self.get_queryset(), name)(*args, **kwargs)
  File "C:\Python310\lib\site-packages\django\db\models\query.py", line 512, in create
    obj = self.model(**kwargs)
  File "C:\Python310\lib\site-packages\django\db\models\base.py", line 559, in __init__
    raise TypeError(
TypeError: Product() got an unexpected keyword argument 'owner'

INFO 2022-04-28 19:05:59,642 basehttp 4216 4940 "POST /products/ HTTP/1.1" 200 56
INFO 2022-04-28 19:05:59,667 basehttp 4216 4940 "GET /favicon.ico HTTP/1.1" 200 66
INFO 2022-04-28 19:06:55,824 autoreload 4216 12852 C:\Users\Lenovo\Documents\projects\InventoryManagementSystem\inventorymanagementsystem\apps\products\views.py changed, reloading.
INFO 2022-04-28 19:06:56,917 autoreload 5804 15796 Watching for file changes with StatReloader
INFO 2022-04-28 19:07:20,069 basehttp 5804 14888 "GET /products/ HTTP/1.1" 200 11817
INFO 2022-04-28 19:07:20,223 basehttp 5804 14888 "GET /favicon.ico HTTP/1.1" 200 66
INFO 2022-04-28 19:07:22,685 basehttp 5804 14888 "GET /products/ HTTP/1.1" 200 11817
INFO 2022-04-28 19:07:22,758 basehttp 5804 14888 "GET /favicon.ico HTTP/1.1" 200 66
INFO 2022-04-28 19:07:26,231 basehttp 5804 14888 "GET /api-auth/logout/?next=/products/ HTTP/1.1" 302 0
INFO 2022-04-28 19:07:26,252 basehttp 5804 14888 "GET /products/ HTTP/1.1" 200 11590
INFO 2022-04-28 19:07:26,331 basehttp 5804 14888 "GET /favicon.ico HTTP/1.1" 200 66
INFO 2022-04-28 19:07:48,391 basehttp 5804 14888 "POST /products/ HTTP/1.1" 201 10313
INFO 2022-04-28 19:07:48,491 basehttp 5804 14888 "GET /favicon.ico HTTP/1.1" 200 66
INFO 2022-04-28 19:08:28,911 basehttp 5804 2876 "POST /products/ HTTP/1.1" 201 133
INFO 2022-04-28 19:11:41,554 autoreload 5804 15796 C:\Users\Lenovo\Documents\projects\InventoryManagementSystem\inventorymanagementsystem\apps\products\models.py changed, reloading.
INFO 2022-04-28 19:11:42,781 autoreload 1364 15560 Watching for file changes with StatReloader
INFO 2022-04-28 19:11:54,971 autoreload 1364 15560 C:\Users\Lenovo\Documents\projects\InventoryManagementSystem\inventorymanagementsystem\apps\products\models.py changed, reloading.
INFO 2022-04-28 19:11:56,046 autoreload 11036 8920 Watching for file changes with StatReloader
INFO 2022-04-28 19:12:00,682 autoreload 11036 8920 C:\Users\Lenovo\Documents\projects\InventoryManagementSystem\inventorymanagementsystem\apps\products\models.py changed, reloading.
INFO 2022-04-28 19:12:01,675 autoreload 12344 15468 Watching for file changes with StatReloader
INFO 2022-04-28 19:12:04,117 autoreload 12344 15468 C:\Users\Lenovo\Documents\projects\InventoryManagementSystem\inventorymanagementsystem\apps\products\models.py changed, reloading.
INFO 2022-04-28 19:12:04,946 autoreload 5348 11504 Watching for file changes with StatReloader
INFO 2022-04-28 19:12:08,457 autoreload 5348 11504 C:\Users\Lenovo\Documents\projects\InventoryManagementSystem\inventorymanagementsystem\apps\products\models.py changed, reloading.
INFO 2022-04-28 19:12:09,517 autoreload 12744 16324 Watching for file changes with StatReloader
INFO 2022-04-28 19:12:28,748 autoreload 12744 16324 C:\Users\Lenovo\Documents\projects\InventoryManagementSystem\inventorymanagementsystem\apps\products\models.py changed, reloading.
INFO 2022-04-28 19:12:29,788 autoreload 15904 13124 Watching for file changes with StatReloader
INFO 2022-04-28 19:12:52,312 autoreload 15904 13124 C:\Users\Lenovo\Documents\projects\InventoryManagementSystem\inventorymanagementsystem\apps\products\models.py changed, reloading.
INFO 2022-04-28 19:12:53,600 autoreload 4324 14356 Watching for file changes with StatReloader
INFO 2022-04-28 19:14:44,686 autoreload 6456 14644 Watching for file changes with StatReloader
INFO 2022-04-28 19:14:51,670 basehttp 6456 14896 "POST /products/ HTTP/1.1" 201 133
INFO 2022-04-28 19:15:13,887 autoreload 6456 14644 C:\Users\Lenovo\Documents\projects\InventoryManagementSystem\inventorymanagementsystem\apps\products\views.py changed, reloading.
INFO 2022-04-28 19:15:15,518 autoreload 14184 9784 Watching for file changes with StatReloader
INFO 2022-04-28 19:15:20,513 log 14184 10080 OK: /products/
Traceback (most recent call last):
  File "C:\Python310\lib\site-packages\django\core\handlers\exception.py", line 55, in inner
    response = get_response(request)
  File "C:\Python310\lib\site-packages\django\core\handlers\base.py", line 197, in _get_response
    response = wrapped_callback(request, *callback_args, **callback_kwargs)
  File "C:\Python310\lib\site-packages\django\views\decorators\csrf.py", line 54, in wrapped_view
    return view_func(*args, **kwargs)
  File "C:\Python310\lib\site-packages\rest_framework\viewsets.py", line 125, in view
    return self.dispatch(request, *args, **kwargs)
  File "C:\Python310\lib\site-packages\rest_framework\views.py", line 509, in dispatch
    response = self.handle_exception(exc)
  File "C:\Python310\lib\site-packages\rest_framework\views.py", line 469, in handle_exception
    self.raise_uncaught_exception(exc)
  File "C:\Python310\lib\site-packages\rest_framework\views.py", line 480, in raise_uncaught_exception
    raise exc
  File "C:\Python310\lib\site-packages\rest_framework\views.py", line 506, in dispatch
    response = handler(request, *args, **kwargs)
  File "C:\Python310\lib\site-packages\rest_framework\mixins.py", line 19, in create
    self.perform_create(serializer)
  File "C:\Users\Lenovo\Documents\projects\InventoryManagementSystem\inventorymanagementsystem\apps\products\views.py", line 43, in perform_create
    serializer.save(owner=self.request.user)
  File "C:\Python310\lib\site-packages\rest_framework\serializers.py", line 212, in save
    self.instance = self.create(validated_data)
  File "C:\Python310\lib\site-packages\rest_framework\serializers.py", line 962, in create
    instance = ModelClass._default_manager.create(**validated_data)
  File "C:\Python310\lib\site-packages\django\db\models\manager.py", line 85, in manager_method
    return getattr(self.get_queryset(), name)(*args, **kwargs)
  File "C:\Python310\lib\site-packages\django\db\models\query.py", line 512, in create
    obj = self.model(**kwargs)
  File "C:\Python310\lib\site-packages\django\db\models\base.py", line 541, in __init__
    _setattr(self, field.name, rel_obj)
  File "C:\Python310\lib\site-packages\django\db\models\fields\related_descriptors.py", line 235, in __set__
    raise ValueError(
ValueError: Cannot assign "<django.contrib.auth.models.AnonymousUser object at 0x000001F29F904C70>": "Product.owner" must be a "User" instance.
INFO 2022-04-28 19:15:20,555 basehttp 14184 10080 "POST /products/ HTTP/1.1" 200 56
INFO 2022-04-28 19:16:30,071 log 14184 15920 OK: /products/
Traceback (most recent call last):
  File "C:\Python310\lib\site-packages\django\core\handlers\exception.py", line 55, in inner
    response = get_response(request)
  File "C:\Python310\lib\site-packages\django\core\handlers\base.py", line 197, in _get_response
    response = wrapped_callback(request, *callback_args, **callback_kwargs)
  File "C:\Python310\lib\site-packages\django\views\decorators\csrf.py", line 54, in wrapped_view
    return view_func(*args, **kwargs)
  File "C:\Python310\lib\site-packages\rest_framework\viewsets.py", line 125, in view
    return self.dispatch(request, *args, **kwargs)
  File "C:\Python310\lib\site-packages\rest_framework\views.py", line 509, in dispatch
    response = self.handle_exception(exc)
  File "C:\Python310\lib\site-packages\rest_framework\views.py", line 469, in handle_exception
    self.raise_uncaught_exception(exc)
  File "C:\Python310\lib\site-packages\rest_framework\views.py", line 480, in raise_uncaught_exception
    raise exc
  File "C:\Python310\lib\site-packages\rest_framework\views.py", line 506, in dispatch
    response = handler(request, *args, **kwargs)
  File "C:\Python310\lib\site-packages\rest_framework\mixins.py", line 19, in create
    self.perform_create(serializer)
  File "C:\Users\Lenovo\Documents\projects\InventoryManagementSystem\inventorymanagementsystem\apps\products\views.py", line 43, in perform_create
    serializer.save(owner=self.request.user)
  File "C:\Python310\lib\site-packages\rest_framework\serializers.py", line 212, in save
    self.instance = self.create(validated_data)
  File "C:\Python310\lib\site-packages\rest_framework\serializers.py", line 962, in create
    instance = ModelClass._default_manager.create(**validated_data)
  File "C:\Python310\lib\site-packages\django\db\models\manager.py", line 85, in manager_method
    return getattr(self.get_queryset(), name)(*args, **kwargs)
  File "C:\Python310\lib\site-packages\django\db\models\query.py", line 512, in create
    obj = self.model(**kwargs)
  File "C:\Python310\lib\site-packages\django\db\models\base.py", line 541, in __init__
    _setattr(self, field.name, rel_obj)
  File "C:\Python310\lib\site-packages\django\db\models\fields\related_descriptors.py", line 235, in __set__
    raise ValueError(
ValueError: Cannot assign "<django.contrib.auth.models.AnonymousUser object at 0x000001F29F831330>": "Product.owner" must be a "User" instance.
INFO 2022-04-28 19:16:30,076 basehttp 14184 15920 "POST /products/ HTTP/1.1" 200 56
INFO 2022-04-28 19:16:30,099 basehttp 14184 15920 "GET /favicon.ico HTTP/1.1" 200 66
INFO 2022-04-28 19:16:32,701 basehttp 14184 15920 "GET /favicon.ico HTTP/1.1" 200 66
INFO 2022-04-28 19:16:35,317 basehttp 14184 15920 "GET /api-auth/login/?next=/products/ HTTP/1.1" 200 2710
INFO 2022-04-28 19:16:35,352 basehttp 14184 15920 "GET /favicon.ico HTTP/1.1" 200 66
INFO 2022-04-28 19:16:38,071 basehttp 14184 15920 "POST /api-auth/login/ HTTP/1.1" 302 0
INFO 2022-04-28 19:16:38,141 basehttp 14184 15920 "GET /products/ HTTP/1.1" 200 12055
INFO 2022-04-28 19:16:38,256 basehttp 14184 15920 "GET /favicon.ico HTTP/1.1" 200 66
INFO 2022-04-28 19:17:03,869 basehttp 14184 15920 "POST /products/ HTTP/1.1" 201 10540
INFO 2022-04-28 19:17:03,980 basehttp 14184 15920 "GET /favicon.ico HTTP/1.1" 200 66
INFO 2022-04-28 19:17:55,806 basehttp 14184 15920 "GET /api-auth/logout/?next=/products/ HTTP/1.1" 302 0
INFO 2022-04-28 19:17:55,829 basehttp 14184 15920 "GET /products/ HTTP/1.1" 200 11828
INFO 2022-04-28 19:17:55,921 basehttp 14184 15920 "GET /favicon.ico HTTP/1.1" 200 66
INFO 2022-04-28 19:18:12,678 log 14184 15920 OK: /products/
Traceback (most recent call last):
  File "C:\Python310\lib\site-packages\django\core\handlers\exception.py", line 55, in inner
    response = get_response(request)
  File "C:\Python310\lib\site-packages\django\core\handlers\base.py", line 197, in _get_response
    response = wrapped_callback(request, *callback_args, **callback_kwargs)
  File "C:\Python310\lib\site-packages\django\views\decorators\csrf.py", line 54, in wrapped_view
    return view_func(*args, **kwargs)
  File "C:\Python310\lib\site-packages\rest_framework\viewsets.py", line 125, in view
    return self.dispatch(request, *args, **kwargs)
  File "C:\Python310\lib\site-packages\rest_framework\views.py", line 509, in dispatch
    response = self.handle_exception(exc)
  File "C:\Python310\lib\site-packages\rest_framework\views.py", line 469, in handle_exception
    self.raise_uncaught_exception(exc)
  File "C:\Python310\lib\site-packages\rest_framework\views.py", line 480, in raise_uncaught_exception
    raise exc
  File "C:\Python310\lib\site-packages\rest_framework\views.py", line 506, in dispatch
    response = handler(request, *args, **kwargs)
  File "C:\Python310\lib\site-packages\rest_framework\mixins.py", line 19, in create
    self.perform_create(serializer)
  File "C:\Users\Lenovo\Documents\projects\InventoryManagementSystem\inventorymanagementsystem\apps\products\views.py", line 43, in perform_create
    serializer.save(owner=self.request.user)
  File "C:\Python310\lib\site-packages\rest_framework\serializers.py", line 212, in save
    self.instance = self.create(validated_data)
  File "C:\Python310\lib\site-packages\rest_framework\serializers.py", line 962, in create
    instance = ModelClass._default_manager.create(**validated_data)
  File "C:\Python310\lib\site-packages\django\db\models\manager.py", line 85, in manager_method
    return getattr(self.get_queryset(), name)(*args, **kwargs)
  File "C:\Python310\lib\site-packages\django\db\models\query.py", line 512, in create
    obj = self.model(**kwargs)
  File "C:\Python310\lib\site-packages\django\db\models\base.py", line 541, in __init__
    _setattr(self, field.name, rel_obj)
  File "C:\Python310\lib\site-packages\django\db\models\fields\related_descriptors.py", line 235, in __set__
    raise ValueError(
ValueError: Cannot assign "<django.contrib.auth.models.AnonymousUser object at 0x000001F29FA2CA30>": "Product.owner" must be a "User" instance.
INFO 2022-04-28 19:18:12,679 basehttp 14184 15920 "POST /products/ HTTP/1.1" 200 56
INFO 2022-04-28 19:18:12,705 basehttp 14184 15920 "GET /favicon.ico HTTP/1.1" 200 66
INFO 2022-04-28 19:18:37,870 basehttp 14184 15920 "GET /products/ HTTP/1.1" 200 11828
INFO 2022-04-28 19:18:38,063 basehttp 14184 15920 "GET /favicon.ico HTTP/1.1" 200 66
INFO 2022-04-28 19:18:39,275 basehttp 14184 15920 "GET /api-auth/login/?next=/products/ HTTP/1.1" 200 2710
INFO 2022-04-28 19:18:39,331 basehttp 14184 15920 "GET /favicon.ico HTTP/1.1" 200 66
INFO 2022-04-28 19:18:42,194 basehttp 14184 15920 "POST /api-auth/login/ HTTP/1.1" 302 0
INFO 2022-04-28 19:18:42,236 basehttp 14184 15920 "GET /products/ HTTP/1.1" 200 12055
INFO 2022-04-28 19:18:42,315 basehttp 14184 15920 "GET /favicon.ico HTTP/1.1" 200 66
INFO 2022-04-29 00:17:35,488 autoreload 15624 10920 Watching for file changes with StatReloader
ERROR 2022-04-29 00:18:35,382 exception 15624 1852 Invalid HTTP_HOST header: '127.0.0.1:8000'. You may need to add '127.0.0.1' to ALLOWED_HOSTS.
WARNING 2022-04-29 00:18:35,383 log 15624 1852 Bad Request: /api-token-auth/
WARNING 2022-04-29 00:18:35,384 basehttp 15624 1852 "POST /api-token-auth/ HTTP/1.1" 400 143
INFO 2022-04-29 00:19:04,171 autoreload 15624 10920 C:\Users\Lenovo\Documents\projects\InventoryManagementSystem\inventorymanagementsystem\inventorymanagementsystem\urls.py changed, reloading.
INFO 2022-04-29 00:19:05,534 autoreload 9820 7212 Watching for file changes with StatReloader
WARNING 2022-04-29 00:20:32,956 log 9820 14028 Bad Request: /api/token/auth/
WARNING 2022-04-29 00:20:32,957 basehttp 9820 14028 "POST /api/token/auth/ HTTP/1.1" 400 97
WARNING 2022-04-29 00:21:33,351 log 9820 14028 Bad Request: /api/token/auth/
WARNING 2022-04-29 00:21:33,351 basehttp 9820 14028 "POST /api/token/auth/?username=sasi&password=1234 HTTP/1.1" 400 97
INFO 2022-04-29 00:22:36,490 basehttp 9820 14028 "POST /api/token/auth/ HTTP/1.1" 200 75
WARNING 2022-04-29 00:23:42,162 log 9820 14028 Unauthorized: /categories/
WARNING 2022-04-29 00:23:42,163 basehttp 9820 14028 "GET /categories/ HTTP/1.1" 401 76
INFO 2022-04-29 00:26:40,016 basehttp 9820 14028 "POST /api/token/auth/ HTTP/1.1" 200 75
INFO 2022-04-29 00:27:15,810 basehttp 9820 14028 "GET /categories/ HTTP/1.1" 200 255
WARNING 2022-04-29 00:27:35,201 log 9820 14028 Unauthorized: /categories/
WARNING 2022-04-29 00:27:35,202 basehttp 9820 14028 "GET /categories/ HTTP/1.1" 401 76
WARNING 2022-04-29 00:27:54,831 log 9820 14028 Method Not Allowed: /api/token/auth/
WARNING 2022-04-29 00:27:54,832 basehttp 9820 14028 "GET /api/token/auth/ HTTP/1.1" 405 58
INFO 2022-04-29 00:28:00,154 basehttp 9820 14028 "POST /api/token/auth/ HTTP/1.1" 200 75
INFO 2022-04-29 09:11:26,061 autoreload 16264 8140 Watching for file changes with StatReloader
INFO 2022-04-29 09:12:07,610 basehttp 16264 13540 "GET /categories/ HTTP/1.1" 200 255
WARNING 2022-04-29 09:12:14,245 log 16264 13540 Unauthorized: /categories/
WARNING 2022-04-29 09:12:14,246 basehttp 16264 13540 "GET /categories/ HTTP/1.1" 401 76
INFO 2022-04-29 09:43:00,006 autoreload 6316 13644 Watching for file changes with StatReloader
WARNING 2022-04-29 09:43:37,090 log 6316 408 Bad Request: /api/token/
WARNING 2022-04-29 09:43:37,091 basehttp 6316 408 "POST /api/token/ HTTP/1.1" 400 97
INFO 2022-04-29 09:44:21,372 basehttp 6316 408 "POST /api/token/ HTTP/1.1" 200 483
INFO 2022-04-29 09:45:29,158 autoreload 6316 13644 C:\Users\Lenovo\Documents\projects\InventoryManagementSystem\inventorymanagementsystem\inventorymanagementsystem\settings.py changed, reloading.
INFO 2022-04-29 09:45:30,437 autoreload 3056 9236 Watching for file changes with StatReloader
WARNING 2022-04-29 09:45:43,462 log 3056 10392 Unauthorized: /categories/
WARNING 2022-04-29 09:45:43,462 basehttp 3056 10392 "GET /categories/ HTTP/1.1" 401 76
INFO 2022-04-29 09:47:08,046 basehttp 3056 10392 "POST /api/token/ HTTP/1.1" 200 483
WARNING 2022-04-29 09:47:43,983 log 3056 10392 Unauthorized: /categories/
WARNING 2022-04-29 09:47:43,984 basehttp 3056 10392 "POST /categories/ HTTP/1.1" 401 76
WARNING 2022-04-29 09:48:58,841 log 3056 10392 Unauthorized: /categories/
WARNING 2022-04-29 09:48:58,841 basehttp 3056 10392 "GET /categories/ HTTP/1.1" 401 76
INFO 2022-04-29 09:51:38,072 basehttp 3056 10392 "POST /api/token/ HTTP/1.1" 200 483
WARNING 2022-04-29 09:52:25,987 log 3056 10392 Unauthorized: /categories/
WARNING 2022-04-29 09:52:25,987 basehttp 3056 10392 "GET /categories/ HTTP/1.1" 401 76
INFO 2022-04-29 09:54:36,990 autoreload 3056 9236 C:\Users\Lenovo\Documents\projects\InventoryManagementSystem\inventorymanagementsystem\apps\products\views.py changed, reloading.
INFO 2022-04-29 09:54:38,544 autoreload 5900 7136 Watching for file changes with StatReloader
INFO 2022-04-29 09:54:40,314 basehttp 5900 11532 "GET /categories/ HTTP/1.1" 200 255
WARNING 2022-04-29 09:54:47,396 log 5900 11532 Unauthorized: /categories/
WARNING 2022-04-29 09:54:47,397 basehttp 5900 11532 "GET /categories/ HTTP/1.1" 401 76
INFO 2022-04-29 09:54:55,099 basehttp 5900 11532 "GET /categories/ HTTP/1.1" 200 255
WARNING 2022-04-29 09:57:36,600 log 5900 11532 Unauthorized: /categories/
WARNING 2022-04-29 09:57:36,601 basehttp 5900 11532 "GET /categories/ HTTP/1.1" 401 76
WARNING 2022-04-29 09:57:42,954 log 5900 11532 Unauthorized: /categories/
WARNING 2022-04-29 09:57:42,955 basehttp 5900 11532 "GET /categories/ HTTP/1.1" 401 201
WARNING 2022-04-29 09:58:13,688 log 5900 11532 Unauthorized: /categories/
WARNING 2022-04-29 09:58:13,689 basehttp 5900 11532 "GET /categories/ HTTP/1.1" 401 76
INFO 2022-04-29 09:58:30,865 autoreload 5900 7136 C:\Users\Lenovo\Documents\projects\InventoryManagementSystem\inventorymanagementsystem\inventorymanagementsystem\settings.py changed, reloading.
INFO 2022-04-29 09:58:31,866 autoreload 3440 8152 Watching for file changes with StatReloader
WARNING 2022-04-29 10:10:22,397 log 3440 484 Unauthorized: /categories/
WARNING 2022-04-29 10:10:22,398 basehttp 3440 484 "GET /categories/ HTTP/1.1" 401 76
INFO 2022-04-29 10:10:40,497 autoreload 3440 8152 C:\Users\Lenovo\Documents\projects\InventoryManagementSystem\inventorymanagementsystem\inventorymanagementsystem\settings.py changed, reloading.
INFO 2022-04-29 10:10:42,123 autoreload 13084 16004 Watching for file changes with StatReloader
INFO 2022-04-29 10:10:43,888 basehttp 13084 16276 "GET /categories/ HTTP/1.1" 200 255
INFO 2022-04-29 12:37:24,431 autoreload 9524 13348 Watching for file changes with StatReloader
INFO 2022-04-29 12:37:28,296 basehttp 9524 248 "GET /products HTTP/1.1" 301 0
WARNING 2022-04-29 12:37:28,307 log 9524 248 Unauthorized: /products/
WARNING 2022-04-29 12:37:28,309 basehttp 9524 248 "GET /products/ HTTP/1.1" 401 76
INFO 2022-04-29 12:38:42,162 basehttp 9524 8140 "GET /products/ HTTP/1.1" 200 12055
INFO 2022-04-29 13:11:53,829 autoreload 9524 13348 C:\Users\Lenovo\Documents\projects\InventoryManagementSystem\inventorymanagementsystem\apps\products\views.py changed, reloading.
INFO 2022-04-29 13:11:55,313 autoreload 9348 15852 Watching for file changes with StatReloader
INFO 2022-04-29 13:12:15,353 autoreload 9348 15852 C:\Users\Lenovo\Documents\projects\InventoryManagementSystem\inventorymanagementsystem\inventorymanagementsystem\settings.py changed, reloading.
INFO 2022-04-29 13:12:16,791 autoreload 10888 10388 Watching for file changes with StatReloader
INFO 2022-04-29 13:12:19,215 autoreload 10888 10388 C:\Users\Lenovo\Documents\projects\InventoryManagementSystem\inventorymanagementsystem\inventorymanagementsystem\settings.py changed, reloading.
INFO 2022-04-29 13:12:20,532 autoreload 124 15900 Watching for file changes with StatReloader
INFO 2022-04-29 13:13:36,389 basehttp 124 15336 "DELETE /categories/3/ HTTP/1.1" 200 30
INFO 2022-04-29 20:46:08,464 autoreload 7448 2316 Watching for file changes with StatReloader
INFO 2022-04-29 20:46:11,826 basehttp 7448 3296 "GET /categories HTTP/1.1" 301 0
INFO 2022-04-29 20:46:11,849 basehttp 7448 3296 "GET /categories/ HTTP/1.1" 200 225
INFO 2022-04-29 20:48:05,365 basehttp 7448 3296 "GET /categories?category=1 HTTP/1.1" 301 0
INFO 2022-04-29 20:48:05,374 basehttp 7448 3296 "GET /categories/?category=1 HTTP/1.1" 200 225
INFO 2022-04-29 20:48:21,946 basehttp 7448 3296 "GET /categories/1 HTTP/1.1" 301 0
WARNING 2022-04-29 20:48:21,958 log 7448 3296 Not Found: /categories/1/
WARNING 2022-04-29 20:48:21,959 basehttp 7448 3296 "GET /categories/1/ HTTP/1.1" 404 41
INFO 2022-04-29 20:48:25,652 basehttp 7448 3296 "GET /categories/2 HTTP/1.1" 301 0
INFO 2022-04-29 20:48:25,670 basehttp 7448 3296 "GET /categories/2/ HTTP/1.1" 200 81
INFO 2022-04-29 20:49:17,581 basehttp 7448 3296 "GET /categories/2 HTTP/1.1" 301 0
INFO 2022-04-29 20:49:17,600 basehttp 7448 3296 "GET /categories/2/ HTTP/1.1" 200 81
WARNING 2022-04-29 20:50:19,995 log 7448 3296 Bad Request: /categories/
WARNING 2022-04-29 20:50:19,995 basehttp 7448 3296 "POST /categories/ HTTP/1.1" 400 54
INFO 2022-04-29 20:54:02,750 basehttp 7448 3296 "GET /categories/ HTTP/1.1" 200 225
INFO 2022-04-29 20:54:15,904 basehttp 7448 3296 "GET /categories/ HTTP/1.1" 200 225
INFO 2022-04-29 20:57:46,739 basehttp 7448 3296 "GET /products HTTP/1.1" 301 0
INFO 2022-04-29 20:57:46,772 basehttp 7448 3296 "GET /products/ HTTP/1.1" 200 355
