INFO 2022-04-18 10:54:10,318 autoreload 2484 10504 Watching for file changes with StatReloader
ERROR 2022-04-18 10:54:14,926 log 2484 7100 Internal Server Error: /orders/
Traceback (most recent call last):
  File "C:\Python310\lib\site-packages\django\core\handlers\exception.py", line 55, in inner
    response = get_response(request)
  File "C:\Python310\lib\site-packages\django\core\handlers\base.py", line 197, in _get_response
    response = wrapped_callback(request, *callback_args, **callback_kwargs)
  File "C:\Python310\lib\site-packages\django\views\decorators\csrf.py", line 54, in wrapped_view
    return view_func(*args, **kwargs)
  File "C:\Python310\lib\site-packages\rest_framework\viewsets.py", line 125, in view
    return self.dispatch(request, *args, **kwargs)
  File "C:\Python310\lib\site-packages\rest_framework\views.py", line 509, in dispatch
    response = self.handle_exception(exc)
  File "C:\Python310\lib\site-packages\rest_framework\views.py", line 469, in handle_exception
    self.raise_uncaught_exception(exc)
  File "C:\Python310\lib\site-packages\rest_framework\views.py", line 480, in raise_uncaught_exception
    raise exc
  File "C:\Python310\lib\site-packages\rest_framework\views.py", line 506, in dispatch
    response = handler(request, *args, **kwargs)
  File "C:\Users\Lenovo\Documents\projects\InventoryManagementSystem\inventorymanagementsystem\apps\orders\orderviews.py", line 38, in create
    new_order = self.order_service.create(validated_data, order_products)
  File "C:\Python310\lib\contextlib.py", line 79, in inner
    return func(*args, **kwds)
  File "C:\Users\Lenovo\Documents\projects\InventoryManagementSystem\inventorymanagementsystem\apps\orders\service.py", line 42, in create
    invoice = self.create_invoice(order_product_data)
  File "C:\Users\Lenovo\Documents\projects\InventoryManagementSystem\inventorymanagementsystem\apps\orders\service.py", line 83, in create_invoice
    print(order_product.data)
AttributeError: 'OrderProduct' object has no attribute 'data'
ERROR 2022-04-18 10:54:14,932 basehttp 2484 7100 "POST /orders/ HTTP/1.1" 500 145
INFO 2022-04-18 10:54:37,818 autoreload 2484 10504 C:\Users\Lenovo\Documents\projects\InventoryManagementSystem\inventorymanagementsystem\apps\orders\service.py changed, reloading.
INFO 2022-04-18 10:54:38,717 autoreload 12936 13496 Watching for file changes with StatReloader
INFO 2022-04-18 10:54:42,244 basehttp 12936 5408 "POST /orders/ HTTP/1.1" 200 164
INFO 2022-04-18 10:55:10,736 autoreload 12936 13496 C:\Users\Lenovo\Documents\projects\InventoryManagementSystem\inventorymanagementsystem\apps\orders\service.py changed, reloading.
INFO 2022-04-18 10:55:11,718 autoreload 7016 1160 Watching for file changes with StatReloader
INFO 2022-04-18 10:55:15,581 basehttp 7016 7340 "POST /orders/ HTTP/1.1" 200 164
INFO 2022-04-18 10:55:26,810 autoreload 7016 1160 C:\Users\Lenovo\Documents\projects\InventoryManagementSystem\inventorymanagementsystem\apps\orders\service.py changed, reloading.
INFO 2022-04-18 10:55:27,813 autoreload 5760 1880 Watching for file changes with StatReloader
INFO 2022-04-18 10:55:33,281 basehttp 5760 10516 "POST /orders/ HTTP/1.1" 200 164
INFO 2022-04-18 10:55:44,127 autoreload 5760 1880 C:\Users\Lenovo\Documents\projects\InventoryManagementSystem\inventorymanagementsystem\apps\orders\service.py changed, reloading.
INFO 2022-04-18 10:55:45,433 autoreload 11440 12836 Watching for file changes with StatReloader
ERROR 2022-04-18 10:55:46,422 log 11440 3424 Internal Server Error: /orders/
Traceback (most recent call last):
  File "C:\Python310\lib\site-packages\django\core\handlers\exception.py", line 55, in inner
    response = get_response(request)
  File "C:\Python310\lib\site-packages\django\core\handlers\base.py", line 197, in _get_response
    response = wrapped_callback(request, *callback_args, **callback_kwargs)
  File "C:\Python310\lib\site-packages\django\views\decorators\csrf.py", line 54, in wrapped_view
    return view_func(*args, **kwargs)
  File "C:\Python310\lib\site-packages\rest_framework\viewsets.py", line 125, in view
    return self.dispatch(request, *args, **kwargs)
  File "C:\Python310\lib\site-packages\rest_framework\views.py", line 509, in dispatch
    response = self.handle_exception(exc)
  File "C:\Python310\lib\site-packages\rest_framework\views.py", line 469, in handle_exception
    self.raise_uncaught_exception(exc)
  File "C:\Python310\lib\site-packages\rest_framework\views.py", line 480, in raise_uncaught_exception
    raise exc
  File "C:\Python310\lib\site-packages\rest_framework\views.py", line 506, in dispatch
    response = handler(request, *args, **kwargs)
  File "C:\Users\Lenovo\Documents\projects\InventoryManagementSystem\inventorymanagementsystem\apps\orders\orderviews.py", line 38, in create
    new_order = self.order_service.create(validated_data, order_products)
  File "C:\Python310\lib\contextlib.py", line 79, in inner
    return func(*args, **kwds)
  File "C:\Users\Lenovo\Documents\projects\InventoryManagementSystem\inventorymanagementsystem\apps\orders\service.py", line 42, in create
    invoice = self.create_invoice(new_order)
  File "C:\Users\Lenovo\Documents\projects\InventoryManagementSystem\inventorymanagementsystem\apps\orders\service.py", line 83, in create_invoice
    print(new_order.data)
AttributeError: 'Order' object has no attribute 'data'
ERROR 2022-04-18 10:55:46,428 basehttp 11440 3424 "POST /orders/ HTTP/1.1" 500 145
INFO 2022-04-18 10:55:50,606 autoreload 11440 12836 C:\Users\Lenovo\Documents\projects\InventoryManagementSystem\inventorymanagementsystem\apps\orders\service.py changed, reloading.
INFO 2022-04-18 10:55:51,559 autoreload 5148 784 Watching for file changes with StatReloader
INFO 2022-04-18 10:55:51,923 basehttp 5148 11248 "POST /orders/ HTTP/1.1" 200 164
INFO 2022-04-18 10:56:04,454 autoreload 5148 784 C:\Users\Lenovo\Documents\projects\InventoryManagementSystem\inventorymanagementsystem\apps\orders\service.py changed, reloading.
INFO 2022-04-18 10:56:05,621 autoreload 5784 3324 Watching for file changes with StatReloader
ERROR 2022-04-18 10:56:08,279 log 5784 12432 Internal Server Error: /orders/
Traceback (most recent call last):
  File "C:\Python310\lib\site-packages\django\core\handlers\exception.py", line 55, in inner
    response = get_response(request)
  File "C:\Python310\lib\site-packages\django\core\handlers\base.py", line 197, in _get_response
    response = wrapped_callback(request, *callback_args, **callback_kwargs)
  File "C:\Python310\lib\site-packages\django\views\decorators\csrf.py", line 54, in wrapped_view
    return view_func(*args, **kwargs)
  File "C:\Python310\lib\site-packages\rest_framework\viewsets.py", line 125, in view
    return self.dispatch(request, *args, **kwargs)
  File "C:\Python310\lib\site-packages\rest_framework\views.py", line 509, in dispatch
    response = self.handle_exception(exc)
  File "C:\Python310\lib\site-packages\rest_framework\views.py", line 469, in handle_exception
    self.raise_uncaught_exception(exc)
  File "C:\Python310\lib\site-packages\rest_framework\views.py", line 480, in raise_uncaught_exception
    raise exc
  File "C:\Python310\lib\site-packages\rest_framework\views.py", line 506, in dispatch
    response = handler(request, *args, **kwargs)
  File "C:\Users\Lenovo\Documents\projects\InventoryManagementSystem\inventorymanagementsystem\apps\orders\orderviews.py", line 38, in create
    new_order = self.order_service.create(validated_data, order_products)
  File "C:\Python310\lib\contextlib.py", line 79, in inner
    return func(*args, **kwds)
  File "C:\Users\Lenovo\Documents\projects\InventoryManagementSystem\inventorymanagementsystem\apps\orders\service.py", line 42, in create
    invoice = self.create_invoice(new_order)
  File "C:\Users\Lenovo\Documents\projects\InventoryManagementSystem\inventorymanagementsystem\apps\orders\service.py", line 83, in create_invoice
    print(new_order.objects.all())
  File "C:\Python310\lib\site-packages\django\db\models\manager.py", line 186, in __get__
    raise AttributeError(
AttributeError: Manager isn't accessible via Order instances
ERROR 2022-04-18 10:56:08,307 basehttp 5784 12432 "POST /orders/ HTTP/1.1" 500 145
INFO 2022-04-18 10:57:23,056 autoreload 5784 3324 C:\Users\Lenovo\Documents\projects\InventoryManagementSystem\inventorymanagementsystem\apps\orders\service.py changed, reloading.
INFO 2022-04-18 10:57:24,056 autoreload 652 8720 Watching for file changes with StatReloader
INFO 2022-04-18 10:57:26,773 basehttp 652 4716 "POST /orders/ HTTP/1.1" 200 164
INFO 2022-04-18 10:57:44,243 autoreload 652 8720 C:\Users\Lenovo\Documents\projects\InventoryManagementSystem\inventorymanagementsystem\apps\orders\service.py changed, reloading.
INFO 2022-04-18 10:57:45,374 autoreload 11656 4664 Watching for file changes with StatReloader
ERROR 2022-04-18 10:57:46,064 log 11656 6100 Internal Server Error: /orders/
Traceback (most recent call last):
  File "C:\Python310\lib\site-packages\django\core\handlers\exception.py", line 55, in inner
    response = get_response(request)
  File "C:\Python310\lib\site-packages\django\core\handlers\base.py", line 197, in _get_response
    response = wrapped_callback(request, *callback_args, **callback_kwargs)
  File "C:\Python310\lib\site-packages\django\views\decorators\csrf.py", line 54, in wrapped_view
    return view_func(*args, **kwargs)
  File "C:\Python310\lib\site-packages\rest_framework\viewsets.py", line 125, in view
    return self.dispatch(request, *args, **kwargs)
  File "C:\Python310\lib\site-packages\rest_framework\views.py", line 509, in dispatch
    response = self.handle_exception(exc)
  File "C:\Python310\lib\site-packages\rest_framework\views.py", line 469, in handle_exception
    self.raise_uncaught_exception(exc)
  File "C:\Python310\lib\site-packages\rest_framework\views.py", line 480, in raise_uncaught_exception
    raise exc
  File "C:\Python310\lib\site-packages\rest_framework\views.py", line 506, in dispatch
    response = handler(request, *args, **kwargs)
  File "C:\Users\Lenovo\Documents\projects\InventoryManagementSystem\inventorymanagementsystem\apps\orders\orderviews.py", line 38, in create
    new_order = self.order_service.create(validated_data, order_products)
  File "C:\Python310\lib\contextlib.py", line 79, in inner
    return func(*args, **kwds)
  File "C:\Users\Lenovo\Documents\projects\InventoryManagementSystem\inventorymanagementsystem\apps\orders\service.py", line 42, in create
    invoice = self.create_invoice(new_order)
  File "C:\Users\Lenovo\Documents\projects\InventoryManagementSystem\inventorymanagementsystem\apps\orders\service.py", line 84, in create_invoice
    print(order_serializer.data['order_products'])
KeyError: 'order_products'
ERROR 2022-04-18 10:57:46,065 basehttp 11656 6100 "POST /orders/ HTTP/1.1" 500 145
INFO 2022-04-18 10:57:58,065 autoreload 11656 4664 C:\Users\Lenovo\Documents\projects\InventoryManagementSystem\inventorymanagementsystem\apps\orders\service.py changed, reloading.
INFO 2022-04-18 10:57:59,183 autoreload 6888 8060 Watching for file changes with StatReloader
INFO 2022-04-18 10:58:05,657 basehttp 6888 11956 "POST /orders/ HTTP/1.1" 200 164
INFO 2022-04-18 10:58:22,471 autoreload 6888 8060 C:\Users\Lenovo\Documents\projects\InventoryManagementSystem\inventorymanagementsystem\apps\orders\service.py changed, reloading.
INFO 2022-04-18 10:58:23,642 autoreload 11492 7056 Watching for file changes with StatReloader
INFO 2022-04-18 10:58:24,741 basehttp 11492 8432 "POST /orders/ HTTP/1.1" 200 164
INFO 2022-04-18 10:59:03,530 autoreload 11492 7056 C:\Users\Lenovo\Documents\projects\InventoryManagementSystem\inventorymanagementsystem\apps\orders\service.py changed, reloading.
INFO 2022-04-18 10:59:04,759 autoreload 3536 9168 Watching for file changes with StatReloader
ERROR 2022-04-18 10:59:05,530 log 3536 5052 Internal Server Error: /orders/
Traceback (most recent call last):
  File "C:\Python310\lib\site-packages\django\core\handlers\exception.py", line 55, in inner
    response = get_response(request)
  File "C:\Python310\lib\site-packages\django\core\handlers\base.py", line 197, in _get_response
    response = wrapped_callback(request, *callback_args, **callback_kwargs)
  File "C:\Python310\lib\site-packages\django\views\decorators\csrf.py", line 54, in wrapped_view
    return view_func(*args, **kwargs)
  File "C:\Python310\lib\site-packages\rest_framework\viewsets.py", line 125, in view
    return self.dispatch(request, *args, **kwargs)
  File "C:\Python310\lib\site-packages\rest_framework\views.py", line 509, in dispatch
    response = self.handle_exception(exc)
  File "C:\Python310\lib\site-packages\rest_framework\views.py", line 469, in handle_exception
    self.raise_uncaught_exception(exc)
  File "C:\Python310\lib\site-packages\rest_framework\views.py", line 480, in raise_uncaught_exception
    raise exc
  File "C:\Python310\lib\site-packages\rest_framework\views.py", line 506, in dispatch
    response = handler(request, *args, **kwargs)
  File "C:\Users\Lenovo\Documents\projects\InventoryManagementSystem\inventorymanagementsystem\apps\orders\orderviews.py", line 38, in create
    new_order = self.order_service.create(validated_data, order_products)
  File "C:\Python310\lib\contextlib.py", line 79, in inner
    return func(*args, **kwds)
  File "C:\Users\Lenovo\Documents\projects\InventoryManagementSystem\inventorymanagementsystem\apps\orders\service.py", line 42, in create
    invoice = self.create_invoice(new_order)
  File "C:\Users\Lenovo\Documents\projects\InventoryManagementSystem\inventorymanagementsystem\apps\orders\service.py", line 84, in create_invoice
    print(order_serializer.data['orderproducts']['product'])
TypeError: list indices must be integers or slices, not str
ERROR 2022-04-18 10:59:05,533 basehttp 3536 5052 "POST /orders/ HTTP/1.1" 500 145
INFO 2022-04-18 10:59:40,777 autoreload 3536 9168 C:\Users\Lenovo\Documents\projects\InventoryManagementSystem\inventorymanagementsystem\apps\orders\service.py changed, reloading.
INFO 2022-04-18 10:59:41,813 autoreload 768 13916 Watching for file changes with StatReloader
INFO 2022-04-18 10:59:43,981 basehttp 768 12252 "POST /orders/ HTTP/1.1" 200 164
INFO 2022-04-18 11:00:08,401 autoreload 768 13916 C:\Users\Lenovo\Documents\projects\InventoryManagementSystem\inventorymanagementsystem\apps\orders\service.py changed, reloading.
INFO 2022-04-18 11:00:09,551 autoreload 12904 1464 Watching for file changes with StatReloader
INFO 2022-04-18 11:00:09,954 basehttp 12904 8768 "POST /orders/ HTTP/1.1" 200 164
INFO 2022-04-18 11:00:27,575 autoreload 12904 1464 C:\Users\Lenovo\Documents\projects\InventoryManagementSystem\inventorymanagementsystem\apps\orders\service.py changed, reloading.
INFO 2022-04-18 11:00:28,633 autoreload 7708 3528 Watching for file changes with StatReloader
INFO 2022-04-18 11:04:21,000 autoreload 7708 3528 C:\Users\Lenovo\Documents\projects\InventoryManagementSystem\inventorymanagementsystem\apps\orders\service.py changed, reloading.
INFO 2022-04-18 11:04:21,925 autoreload 11752 108 Watching for file changes with StatReloader
ERROR 2022-04-18 11:04:27,065 log 11752 7824 Internal Server Error: /orders/
Traceback (most recent call last):
  File "C:\Python310\lib\site-packages\django\core\handlers\exception.py", line 55, in inner
    response = get_response(request)
  File "C:\Python310\lib\site-packages\django\core\handlers\base.py", line 197, in _get_response
    response = wrapped_callback(request, *callback_args, **callback_kwargs)
  File "C:\Python310\lib\site-packages\django\views\decorators\csrf.py", line 54, in wrapped_view
    return view_func(*args, **kwargs)
  File "C:\Python310\lib\site-packages\rest_framework\viewsets.py", line 125, in view
    return self.dispatch(request, *args, **kwargs)
  File "C:\Python310\lib\site-packages\rest_framework\views.py", line 509, in dispatch
    response = self.handle_exception(exc)
  File "C:\Python310\lib\site-packages\rest_framework\views.py", line 469, in handle_exception
    self.raise_uncaught_exception(exc)
  File "C:\Python310\lib\site-packages\rest_framework\views.py", line 480, in raise_uncaught_exception
    raise exc
  File "C:\Python310\lib\site-packages\rest_framework\views.py", line 506, in dispatch
    response = handler(request, *args, **kwargs)
  File "C:\Users\Lenovo\Documents\projects\InventoryManagementSystem\inventorymanagementsystem\apps\orders\orderviews.py", line 38, in create
    new_order = self.order_service.create(validated_data, order_products)
  File "C:\Python310\lib\contextlib.py", line 79, in inner
    return func(*args, **kwds)
  File "C:\Users\Lenovo\Documents\projects\InventoryManagementSystem\inventorymanagementsystem\apps\orders\service.py", line 42, in create
    invoice = self.create_invoice(new_order)
  File "C:\Users\Lenovo\Documents\projects\InventoryManagementSystem\inventorymanagementsystem\apps\orders\service.py", line 87, in create_invoice
    product = products.get(id=order['product'])
NameError: name 'order' is not defined
ERROR 2022-04-18 11:04:27,078 basehttp 11752 7824 "POST /orders/ HTTP/1.1" 500 145
INFO 2022-04-18 11:04:58,535 autoreload 11752 108 C:\Users\Lenovo\Documents\projects\InventoryManagementSystem\inventorymanagementsystem\apps\orders\service.py changed, reloading.
INFO 2022-04-18 11:04:59,800 autoreload 13152 9600 Watching for file changes with StatReloader
INFO 2022-04-18 11:05:01,975 basehttp 13152 524 "POST /orders/ HTTP/1.1" 200 164
INFO 2022-04-18 11:06:03,586 autoreload 13152 9600 C:\Users\Lenovo\Documents\projects\InventoryManagementSystem\inventorymanagementsystem\apps\orders\service.py changed, reloading.
INFO 2022-04-18 11:06:04,443 autoreload 3184 7896 Watching for file changes with StatReloader
INFO 2022-04-18 11:08:19,440 autoreload 3184 7896 C:\Users\Lenovo\Documents\projects\InventoryManagementSystem\inventorymanagementsystem\apps\orders\service.py changed, reloading.
INFO 2022-04-18 11:08:20,331 autoreload 12816 11288 Watching for file changes with StatReloader
INFO 2022-04-18 11:08:25,302 autoreload 12816 11288 C:\Users\Lenovo\Documents\projects\InventoryManagementSystem\inventorymanagementsystem\apps\orders\service.py changed, reloading.
INFO 2022-04-18 11:08:26,499 autoreload 13900 1956 Watching for file changes with StatReloader
ERROR 2022-04-18 11:08:28,132 log 13900 2772 Internal Server Error: /orders/
Traceback (most recent call last):
  File "C:\Python310\lib\site-packages\django\core\handlers\exception.py", line 55, in inner
    response = get_response(request)
  File "C:\Python310\lib\site-packages\django\core\handlers\base.py", line 197, in _get_response
    response = wrapped_callback(request, *callback_args, **callback_kwargs)
  File "C:\Python310\lib\site-packages\django\views\decorators\csrf.py", line 54, in wrapped_view
    return view_func(*args, **kwargs)
  File "C:\Python310\lib\site-packages\rest_framework\viewsets.py", line 125, in view
    return self.dispatch(request, *args, **kwargs)
  File "C:\Python310\lib\site-packages\rest_framework\views.py", line 509, in dispatch
    response = self.handle_exception(exc)
  File "C:\Python310\lib\site-packages\rest_framework\views.py", line 469, in handle_exception
    self.raise_uncaught_exception(exc)
  File "C:\Python310\lib\site-packages\rest_framework\views.py", line 480, in raise_uncaught_exception
    raise exc
  File "C:\Python310\lib\site-packages\rest_framework\views.py", line 506, in dispatch
    response = handler(request, *args, **kwargs)
  File "C:\Users\Lenovo\Documents\projects\InventoryManagementSystem\inventorymanagementsystem\apps\orders\orderviews.py", line 38, in create
    new_order = self.order_service.create(validated_data, order_products)
  File "C:\Python310\lib\contextlib.py", line 79, in inner
    return func(*args, **kwds)
  File "C:\Users\Lenovo\Documents\projects\InventoryManagementSystem\inventorymanagementsystem\apps\orders\service.py", line 43, in create
    invoice = self.create_invoice(new_order)
  File "C:\Users\Lenovo\Documents\projects\InventoryManagementSystem\inventorymanagementsystem\apps\orders\service.py", line 94, in create_invoice
    payment_deadline = created_date + 15
TypeError: unsupported operand type(s) for +: 'builtin_function_or_method' and 'int'
ERROR 2022-04-18 11:08:28,139 basehttp 13900 2772 "POST /orders/ HTTP/1.1" 500 145
INFO 2022-04-18 11:26:22,303 autoreload 13900 1956 C:\Users\Lenovo\Documents\projects\InventoryManagementSystem\inventorymanagementsystem\apps\orders\service.py changed, reloading.
INFO 2022-04-18 11:26:23,224 autoreload 7572 6424 Watching for file changes with StatReloader
INFO 2022-04-18 11:26:31,234 autoreload 7572 6424 C:\Users\Lenovo\Documents\projects\InventoryManagementSystem\inventorymanagementsystem\apps\orders\service.py changed, reloading.
INFO 2022-04-18 11:26:32,324 autoreload 10416 13220 Watching for file changes with StatReloader
INFO 2022-04-18 11:26:39,448 autoreload 10416 13220 C:\Users\Lenovo\Documents\projects\InventoryManagementSystem\inventorymanagementsystem\apps\orders\service.py changed, reloading.
INFO 2022-04-18 11:26:40,303 autoreload 12168 7208 Watching for file changes with StatReloader
ERROR 2022-04-18 11:26:44,565 log 12168 11896 Internal Server Error: /orders/
Traceback (most recent call last):
  File "C:\Python310\lib\site-packages\django\core\handlers\exception.py", line 55, in inner
    response = get_response(request)
  File "C:\Python310\lib\site-packages\django\core\handlers\base.py", line 197, in _get_response
    response = wrapped_callback(request, *callback_args, **callback_kwargs)
  File "C:\Python310\lib\site-packages\django\views\decorators\csrf.py", line 54, in wrapped_view
    return view_func(*args, **kwargs)
  File "C:\Python310\lib\site-packages\rest_framework\viewsets.py", line 125, in view
    return self.dispatch(request, *args, **kwargs)
  File "C:\Python310\lib\site-packages\rest_framework\views.py", line 509, in dispatch
    response = self.handle_exception(exc)
  File "C:\Python310\lib\site-packages\rest_framework\views.py", line 469, in handle_exception
    self.raise_uncaught_exception(exc)
  File "C:\Python310\lib\site-packages\rest_framework\views.py", line 480, in raise_uncaught_exception
    raise exc
  File "C:\Python310\lib\site-packages\rest_framework\views.py", line 506, in dispatch
    response = handler(request, *args, **kwargs)
  File "C:\Users\Lenovo\Documents\projects\InventoryManagementSystem\inventorymanagementsystem\apps\orders\orderviews.py", line 38, in create
    new_order = self.order_service.create(validated_data, order_products)
  File "C:\Python310\lib\contextlib.py", line 79, in inner
    return func(*args, **kwds)
  File "C:\Users\Lenovo\Documents\projects\InventoryManagementSystem\inventorymanagementsystem\apps\orders\service.py", line 43, in create
    invoice = self.create_invoice(new_order)
  File "C:\Users\Lenovo\Documents\projects\InventoryManagementSystem\inventorymanagementsystem\apps\orders\service.py", line 94, in create_invoice
    payment_deadline = created_date + datetime.timedelta(days=15)
TypeError: unsupported operand type(s) for +: 'builtin_function_or_method' and 'datetime.timedelta'
ERROR 2022-04-18 11:26:44,576 basehttp 12168 11896 "POST /orders/ HTTP/1.1" 500 145
INFO 2022-04-18 11:27:30,637 autoreload 12168 7208 C:\Users\Lenovo\Documents\projects\InventoryManagementSystem\inventorymanagementsystem\apps\orders\service.py changed, reloading.
INFO 2022-04-18 11:27:31,483 autoreload 11708 10204 Watching for file changes with StatReloader
ERROR 2022-04-18 11:27:33,949 log 11708 2744 Internal Server Error: /orders/
Traceback (most recent call last):
  File "C:\Python310\lib\site-packages\django\core\handlers\exception.py", line 55, in inner
    response = get_response(request)
  File "C:\Python310\lib\site-packages\django\core\handlers\base.py", line 197, in _get_response
    response = wrapped_callback(request, *callback_args, **callback_kwargs)
  File "C:\Python310\lib\site-packages\django\views\decorators\csrf.py", line 54, in wrapped_view
    return view_func(*args, **kwargs)
  File "C:\Python310\lib\site-packages\rest_framework\viewsets.py", line 125, in view
    return self.dispatch(request, *args, **kwargs)
  File "C:\Python310\lib\site-packages\rest_framework\views.py", line 509, in dispatch
    response = self.handle_exception(exc)
  File "C:\Python310\lib\site-packages\rest_framework\views.py", line 469, in handle_exception
    self.raise_uncaught_exception(exc)
  File "C:\Python310\lib\site-packages\rest_framework\views.py", line 480, in raise_uncaught_exception
    raise exc
  File "C:\Python310\lib\site-packages\rest_framework\views.py", line 506, in dispatch
    response = handler(request, *args, **kwargs)
  File "C:\Users\Lenovo\Documents\projects\InventoryManagementSystem\inventorymanagementsystem\apps\orders\orderviews.py", line 38, in create
    new_order = self.order_service.create(validated_data, order_products)
  File "C:\Python310\lib\contextlib.py", line 79, in inner
    return func(*args, **kwds)
  File "C:\Users\Lenovo\Documents\projects\InventoryManagementSystem\inventorymanagementsystem\apps\orders\service.py", line 43, in create
    invoice = self.create_invoice(new_order)
  File "C:\Users\Lenovo\Documents\projects\InventoryManagementSystem\inventorymanagementsystem\apps\orders\service.py", line 94, in create_invoice
    payment_deadline = created_date.date() + datetime.timedelta(days=15)
AttributeError: 'builtin_function_or_method' object has no attribute 'date'
ERROR 2022-04-18 11:27:33,952 basehttp 11708 2744 "POST /orders/ HTTP/1.1" 500 145
ERROR 2022-04-18 11:27:36,843 log 11708 2744 Internal Server Error: /orders/
Traceback (most recent call last):
  File "C:\Python310\lib\site-packages\django\core\handlers\exception.py", line 55, in inner
    response = get_response(request)
  File "C:\Python310\lib\site-packages\django\core\handlers\base.py", line 197, in _get_response
    response = wrapped_callback(request, *callback_args, **callback_kwargs)
  File "C:\Python310\lib\site-packages\django\views\decorators\csrf.py", line 54, in wrapped_view
    return view_func(*args, **kwargs)
  File "C:\Python310\lib\site-packages\rest_framework\viewsets.py", line 125, in view
    return self.dispatch(request, *args, **kwargs)
  File "C:\Python310\lib\site-packages\rest_framework\views.py", line 509, in dispatch
    response = self.handle_exception(exc)
  File "C:\Python310\lib\site-packages\rest_framework\views.py", line 469, in handle_exception
    self.raise_uncaught_exception(exc)
  File "C:\Python310\lib\site-packages\rest_framework\views.py", line 480, in raise_uncaught_exception
    raise exc
  File "C:\Python310\lib\site-packages\rest_framework\views.py", line 506, in dispatch
    response = handler(request, *args, **kwargs)
  File "C:\Users\Lenovo\Documents\projects\InventoryManagementSystem\inventorymanagementsystem\apps\orders\orderviews.py", line 38, in create
    new_order = self.order_service.create(validated_data, order_products)
  File "C:\Python310\lib\contextlib.py", line 79, in inner
    return func(*args, **kwds)
  File "C:\Users\Lenovo\Documents\projects\InventoryManagementSystem\inventorymanagementsystem\apps\orders\service.py", line 43, in create
    invoice = self.create_invoice(new_order)
  File "C:\Users\Lenovo\Documents\projects\InventoryManagementSystem\inventorymanagementsystem\apps\orders\service.py", line 94, in create_invoice
    payment_deadline = created_date.date() + datetime.timedelta(days=15)
AttributeError: 'builtin_function_or_method' object has no attribute 'date'
ERROR 2022-04-18 11:27:36,845 basehttp 11708 2744 "POST /orders/ HTTP/1.1" 500 145
INFO 2022-04-18 11:28:34,681 autoreload 11708 10204 C:\Users\Lenovo\Documents\projects\InventoryManagementSystem\inventorymanagementsystem\apps\orders\service.py changed, reloading.
INFO 2022-04-18 11:28:35,813 autoreload 5752 11484 Watching for file changes with StatReloader
ERROR 2022-04-18 11:28:37,831 log 5752 7928 Internal Server Error: /orders/
Traceback (most recent call last):
  File "C:\Python310\lib\site-packages\django\core\handlers\exception.py", line 55, in inner
    response = get_response(request)
  File "C:\Python310\lib\site-packages\django\core\handlers\base.py", line 197, in _get_response
    response = wrapped_callback(request, *callback_args, **callback_kwargs)
  File "C:\Python310\lib\site-packages\django\views\decorators\csrf.py", line 54, in wrapped_view
    return view_func(*args, **kwargs)
  File "C:\Python310\lib\site-packages\rest_framework\viewsets.py", line 125, in view
    return self.dispatch(request, *args, **kwargs)
  File "C:\Python310\lib\site-packages\rest_framework\views.py", line 509, in dispatch
    response = self.handle_exception(exc)
  File "C:\Python310\lib\site-packages\rest_framework\views.py", line 469, in handle_exception
    self.raise_uncaught_exception(exc)
  File "C:\Python310\lib\site-packages\rest_framework\views.py", line 480, in raise_uncaught_exception
    raise exc
  File "C:\Python310\lib\site-packages\rest_framework\views.py", line 506, in dispatch
    response = handler(request, *args, **kwargs)
  File "C:\Users\Lenovo\Documents\projects\InventoryManagementSystem\inventorymanagementsystem\apps\orders\orderviews.py", line 38, in create
    new_order = self.order_service.create(validated_data, order_products)
  File "C:\Python310\lib\contextlib.py", line 79, in inner
    return func(*args, **kwds)
  File "C:\Users\Lenovo\Documents\projects\InventoryManagementSystem\inventorymanagementsystem\apps\orders\service.py", line 43, in create
    invoice = self.create_invoice(new_order)
  File "C:\Users\Lenovo\Documents\projects\InventoryManagementSystem\inventorymanagementsystem\apps\orders\service.py", line 94, in create_invoice
    payment_deadline = created_date + datetime.timedelta(days=15)
TypeError: unsupported operand type(s) for +: 'builtin_function_or_method' and 'datetime.timedelta'
ERROR 2022-04-18 11:28:37,834 basehttp 5752 7928 "POST /orders/ HTTP/1.1" 500 145
INFO 2022-04-18 11:29:16,119 autoreload 5752 11484 C:\Users\Lenovo\Documents\projects\InventoryManagementSystem\inventorymanagementsystem\apps\orders\service.py changed, reloading.
INFO 2022-04-18 11:29:17,054 autoreload 11424 5832 Watching for file changes with StatReloader
INFO 2022-04-18 11:29:26,523 autoreload 11424 5832 C:\Users\Lenovo\Documents\projects\InventoryManagementSystem\inventorymanagementsystem\apps\orders\service.py changed, reloading.
INFO 2022-04-18 11:29:27,494 autoreload 12828 1864 Watching for file changes with StatReloader
INFO 2022-04-18 11:29:31,328 autoreload 12828 1864 C:\Users\Lenovo\Documents\projects\InventoryManagementSystem\inventorymanagementsystem\apps\orders\service.py changed, reloading.
INFO 2022-04-18 11:29:32,410 autoreload 9980 10684 Watching for file changes with StatReloader
INFO 2022-04-18 11:30:02,559 autoreload 9980 10684 C:\Users\Lenovo\Documents\projects\InventoryManagementSystem\inventorymanagementsystem\apps\orders\service.py changed, reloading.
INFO 2022-04-18 11:30:03,446 autoreload 8056 6248 Watching for file changes with StatReloader
INFO 2022-04-18 11:30:13,946 autoreload 8056 6248 C:\Users\Lenovo\Documents\projects\InventoryManagementSystem\inventorymanagementsystem\apps\orders\service.py changed, reloading.
INFO 2022-04-18 11:30:14,987 autoreload 11008 1512 Watching for file changes with StatReloader
ERROR 2022-04-18 11:30:16,845 log 11008 5972 Internal Server Error: /orders/
Traceback (most recent call last):
  File "C:\Python310\lib\site-packages\django\core\handlers\exception.py", line 55, in inner
    response = get_response(request)
  File "C:\Python310\lib\site-packages\django\core\handlers\base.py", line 197, in _get_response
    response = wrapped_callback(request, *callback_args, **callback_kwargs)
  File "C:\Python310\lib\site-packages\django\views\decorators\csrf.py", line 54, in wrapped_view
    return view_func(*args, **kwargs)
  File "C:\Python310\lib\site-packages\rest_framework\viewsets.py", line 125, in view
    return self.dispatch(request, *args, **kwargs)
  File "C:\Python310\lib\site-packages\rest_framework\views.py", line 509, in dispatch
    response = self.handle_exception(exc)
  File "C:\Python310\lib\site-packages\rest_framework\views.py", line 469, in handle_exception
    self.raise_uncaught_exception(exc)
  File "C:\Python310\lib\site-packages\rest_framework\views.py", line 480, in raise_uncaught_exception
    raise exc
  File "C:\Python310\lib\site-packages\rest_framework\views.py", line 506, in dispatch
    response = handler(request, *args, **kwargs)
  File "C:\Users\Lenovo\Documents\projects\InventoryManagementSystem\inventorymanagementsystem\apps\orders\orderviews.py", line 38, in create
    new_order = self.order_service.create(validated_data, order_products)
  File "C:\Python310\lib\contextlib.py", line 79, in inner
    return func(*args, **kwds)
  File "C:\Users\Lenovo\Documents\projects\InventoryManagementSystem\inventorymanagementsystem\apps\orders\service.py", line 43, in create
    invoice = self.create_invoice(new_order)
  File "C:\Users\Lenovo\Documents\projects\InventoryManagementSystem\inventorymanagementsystem\apps\orders\service.py", line 93, in create_invoice
    created_date = date.today
NameError: name 'date' is not defined
ERROR 2022-04-18 11:30:16,851 basehttp 11008 5972 "POST /orders/ HTTP/1.1" 500 145
INFO 2022-04-18 11:30:44,345 autoreload 11008 1512 C:\Users\Lenovo\Documents\projects\InventoryManagementSystem\inventorymanagementsystem\apps\orders\service.py changed, reloading.
INFO 2022-04-18 11:30:45,255 autoreload 9260 3388 Watching for file changes with StatReloader
ERROR 2022-04-18 11:30:57,160 log 9260 1780 Internal Server Error: /orders/
Traceback (most recent call last):
  File "C:\Python310\lib\site-packages\django\core\handlers\exception.py", line 55, in inner
    response = get_response(request)
  File "C:\Python310\lib\site-packages\django\core\handlers\base.py", line 197, in _get_response
    response = wrapped_callback(request, *callback_args, **callback_kwargs)
  File "C:\Python310\lib\site-packages\django\views\decorators\csrf.py", line 54, in wrapped_view
    return view_func(*args, **kwargs)
  File "C:\Python310\lib\site-packages\rest_framework\viewsets.py", line 125, in view
    return self.dispatch(request, *args, **kwargs)
  File "C:\Python310\lib\site-packages\rest_framework\views.py", line 509, in dispatch
    response = self.handle_exception(exc)
  File "C:\Python310\lib\site-packages\rest_framework\views.py", line 469, in handle_exception
    self.raise_uncaught_exception(exc)
  File "C:\Python310\lib\site-packages\rest_framework\views.py", line 480, in raise_uncaught_exception
    raise exc
  File "C:\Python310\lib\site-packages\rest_framework\views.py", line 506, in dispatch
    response = handler(request, *args, **kwargs)
  File "C:\Users\Lenovo\Documents\projects\InventoryManagementSystem\inventorymanagementsystem\apps\orders\orderviews.py", line 38, in create
    new_order = self.order_service.create(validated_data, order_products)
  File "C:\Python310\lib\contextlib.py", line 79, in inner
    return func(*args, **kwds)
  File "C:\Users\Lenovo\Documents\projects\InventoryManagementSystem\inventorymanagementsystem\apps\orders\service.py", line 43, in create
    invoice = self.create_invoice(new_order)
  File "C:\Users\Lenovo\Documents\projects\InventoryManagementSystem\inventorymanagementsystem\apps\orders\service.py", line 93, in create_invoice
    created_date = datetime.date.today
AttributeError: 'method_descriptor' object has no attribute 'today'
ERROR 2022-04-18 11:30:57,164 basehttp 9260 1780 "POST /orders/ HTTP/1.1" 500 145
INFO 2022-04-18 11:31:45,270 autoreload 9260 3388 C:\Users\Lenovo\Documents\projects\InventoryManagementSystem\inventorymanagementsystem\apps\orders\service.py changed, reloading.
INFO 2022-04-18 11:31:46,252 autoreload 5916 3216 Watching for file changes with StatReloader
ERROR 2022-04-18 11:31:48,076 log 5916 6152 Internal Server Error: /orders/
Traceback (most recent call last):
  File "C:\Python310\lib\site-packages\django\core\handlers\exception.py", line 55, in inner
    response = get_response(request)
  File "C:\Python310\lib\site-packages\django\core\handlers\base.py", line 197, in _get_response
    response = wrapped_callback(request, *callback_args, **callback_kwargs)
  File "C:\Python310\lib\site-packages\django\views\decorators\csrf.py", line 54, in wrapped_view
    return view_func(*args, **kwargs)
  File "C:\Python310\lib\site-packages\rest_framework\viewsets.py", line 125, in view
    return self.dispatch(request, *args, **kwargs)
  File "C:\Python310\lib\site-packages\rest_framework\views.py", line 509, in dispatch
    response = self.handle_exception(exc)
  File "C:\Python310\lib\site-packages\rest_framework\views.py", line 469, in handle_exception
    self.raise_uncaught_exception(exc)
  File "C:\Python310\lib\site-packages\rest_framework\views.py", line 480, in raise_uncaught_exception
    raise exc
  File "C:\Python310\lib\site-packages\rest_framework\views.py", line 506, in dispatch
    response = handler(request, *args, **kwargs)
  File "C:\Users\Lenovo\Documents\projects\InventoryManagementSystem\inventorymanagementsystem\apps\orders\orderviews.py", line 38, in create
    new_order = self.order_service.create(validated_data, order_products)
  File "C:\Python310\lib\contextlib.py", line 79, in inner
    return func(*args, **kwds)
  File "C:\Users\Lenovo\Documents\projects\InventoryManagementSystem\inventorymanagementsystem\apps\orders\service.py", line 43, in create
    invoice = self.create_invoice(new_order)
  File "C:\Users\Lenovo\Documents\projects\InventoryManagementSystem\inventorymanagementsystem\apps\orders\service.py", line 95, in create_invoice
    payment_deadline = created_date + datetime.timedelta(days=15)
NameError: name 'datetime' is not defined
ERROR 2022-04-18 11:31:48,083 basehttp 5916 6152 "POST /orders/ HTTP/1.1" 500 145
INFO 2022-04-18 11:32:04,695 autoreload 5916 3216 C:\Users\Lenovo\Documents\projects\InventoryManagementSystem\inventorymanagementsystem\apps\orders\service.py changed, reloading.
INFO 2022-04-18 11:32:05,687 autoreload 4820 2532 Watching for file changes with StatReloader
INFO 2022-04-18 11:32:08,802 basehttp 4820 9548 "POST /orders/ HTTP/1.1" 200 164
INFO 2022-04-18 11:32:53,540 autoreload 4820 2532 C:\Users\Lenovo\Documents\projects\InventoryManagementSystem\inventorymanagementsystem\apps\orders\service.py changed, reloading.
INFO 2022-04-18 11:32:54,532 autoreload 2276 7868 Watching for file changes with StatReloader
INFO 2022-04-18 11:35:52,514 autoreload 9492 13428 Watching for file changes with StatReloader
INFO 2022-04-18 11:38:40,023 autoreload 9492 13428 C:\Users\Lenovo\Documents\projects\InventoryManagementSystem\inventorymanagementsystem\apps\orders\service.py changed, reloading.
INFO 2022-04-18 11:38:41,065 autoreload 1880 7312 Watching for file changes with StatReloader
INFO 2022-04-18 11:39:05,770 autoreload 1880 7312 C:\Users\Lenovo\Documents\projects\InventoryManagementSystem\inventorymanagementsystem\apps\orders\service.py changed, reloading.
INFO 2022-04-18 11:39:06,673 autoreload 7516 9648 Watching for file changes with StatReloader
ERROR 2022-04-18 11:39:32,302 log 7516 2900 Internal Server Error: /orders/
Traceback (most recent call last):
  File "C:\Python310\lib\site-packages\django\db\backends\utils.py", line 89, in _execute
    return self.cursor.execute(sql, params)
  File "C:\Python310\lib\site-packages\django\db\backends\mysql\base.py", line 75, in execute
    return self.cursor.execute(query, args)
  File "C:\Python310\lib\site-packages\MySQLdb\cursors.py", line 206, in execute
    res = self._query(query)
  File "C:\Python310\lib\site-packages\MySQLdb\cursors.py", line 319, in _query
    db.query(q)
  File "C:\Python310\lib\site-packages\MySQLdb\connections.py", line 254, in query
    _mysql.connection.query(self, query)
MySQLdb._exceptions.DataError: (1264, "Out of range value for column 'amount' at row 1")

The above exception was the direct cause of the following exception:

Traceback (most recent call last):
  File "C:\Python310\lib\site-packages\django\core\handlers\exception.py", line 55, in inner
    response = get_response(request)
  File "C:\Python310\lib\site-packages\django\core\handlers\base.py", line 197, in _get_response
    response = wrapped_callback(request, *callback_args, **callback_kwargs)
  File "C:\Python310\lib\site-packages\django\views\decorators\csrf.py", line 54, in wrapped_view
    return view_func(*args, **kwargs)
  File "C:\Python310\lib\site-packages\rest_framework\viewsets.py", line 125, in view
    return self.dispatch(request, *args, **kwargs)
  File "C:\Python310\lib\site-packages\rest_framework\views.py", line 509, in dispatch
    response = self.handle_exception(exc)
  File "C:\Python310\lib\site-packages\rest_framework\views.py", line 469, in handle_exception
    self.raise_uncaught_exception(exc)
  File "C:\Python310\lib\site-packages\rest_framework\views.py", line 480, in raise_uncaught_exception
    raise exc
  File "C:\Python310\lib\site-packages\rest_framework\views.py", line 506, in dispatch
    response = handler(request, *args, **kwargs)
  File "C:\Users\Lenovo\Documents\projects\InventoryManagementSystem\inventorymanagementsystem\apps\orders\orderviews.py", line 38, in create
    new_order = self.order_service.create(validated_data, order_products)
  File "C:\Python310\lib\contextlib.py", line 79, in inner
    return func(*args, **kwds)
  File "C:\Users\Lenovo\Documents\projects\InventoryManagementSystem\inventorymanagementsystem\apps\orders\service.py", line 43, in create
    invoice = self.create_invoice(new_order)
  File "C:\Users\Lenovo\Documents\projects\InventoryManagementSystem\inventorymanagementsystem\apps\orders\service.py", line 96, in create_invoice
    invoice = Invoice.objects.create(amount=amount, created_date=created_date,
  File "C:\Python310\lib\site-packages\django\db\models\manager.py", line 85, in manager_method
    return getattr(self.get_queryset(), name)(*args, **kwargs)
  File "C:\Python310\lib\site-packages\django\db\models\query.py", line 514, in create
    obj.save(force_insert=True, using=self.db)
  File "C:\Python310\lib\site-packages\django\db\models\base.py", line 806, in save
    self.save_base(
  File "C:\Python310\lib\site-packages\django\db\models\base.py", line 857, in save_base
    updated = self._save_table(
  File "C:\Python310\lib\site-packages\django\db\models\base.py", line 1000, in _save_table
    results = self._do_insert(
  File "C:\Python310\lib\site-packages\django\db\models\base.py", line 1041, in _do_insert
    return manager._insert(
  File "C:\Python310\lib\site-packages\django\db\models\manager.py", line 85, in manager_method
    return getattr(self.get_queryset(), name)(*args, **kwargs)
  File "C:\Python310\lib\site-packages\django\db\models\query.py", line 1434, in _insert
    return query.get_compiler(using=using).execute_sql(returning_fields)
  File "C:\Python310\lib\site-packages\django\db\models\sql\compiler.py", line 1621, in execute_sql
    cursor.execute(sql, params)
  File "C:\Python310\lib\site-packages\django\db\backends\utils.py", line 67, in execute
    return self._execute_with_wrappers(
  File "C:\Python310\lib\site-packages\django\db\backends\utils.py", line 80, in _execute_with_wrappers
    return executor(sql, params, many, context)
  File "C:\Python310\lib\site-packages\django\db\backends\utils.py", line 84, in _execute
    with self.db.wrap_database_errors:
  File "C:\Python310\lib\site-packages\django\db\utils.py", line 91, in __exit__
    raise dj_exc_value.with_traceback(traceback) from exc_value
  File "C:\Python310\lib\site-packages\django\db\backends\utils.py", line 89, in _execute
    return self.cursor.execute(sql, params)
  File "C:\Python310\lib\site-packages\django\db\backends\mysql\base.py", line 75, in execute
    return self.cursor.execute(query, args)
  File "C:\Python310\lib\site-packages\MySQLdb\cursors.py", line 206, in execute
    res = self._query(query)
  File "C:\Python310\lib\site-packages\MySQLdb\cursors.py", line 319, in _query
    db.query(q)
  File "C:\Python310\lib\site-packages\MySQLdb\connections.py", line 254, in query
    _mysql.connection.query(self, query)
django.db.utils.DataError: (1264, "Out of range value for column 'amount' at row 1")
ERROR 2022-04-18 11:39:32,439 basehttp 7516 2900 "POST /orders/ HTTP/1.1" 500 145
INFO 2022-04-18 11:40:10,681 autoreload 7516 9648 C:\Users\Lenovo\Documents\projects\InventoryManagementSystem\inventorymanagementsystem\apps\orders\service.py changed, reloading.
INFO 2022-04-18 11:40:11,584 autoreload 12192 14044 Watching for file changes with StatReloader
ERROR 2022-04-18 11:40:16,942 log 12192 10892 Internal Server Error: /orders/
Traceback (most recent call last):
  File "C:\Python310\lib\site-packages\django\core\handlers\exception.py", line 55, in inner
    response = get_response(request)
  File "C:\Python310\lib\site-packages\django\core\handlers\base.py", line 197, in _get_response
    response = wrapped_callback(request, *callback_args, **callback_kwargs)
  File "C:\Python310\lib\site-packages\django\views\decorators\csrf.py", line 54, in wrapped_view
    return view_func(*args, **kwargs)
  File "C:\Python310\lib\site-packages\rest_framework\viewsets.py", line 125, in view
    return self.dispatch(request, *args, **kwargs)
  File "C:\Python310\lib\site-packages\rest_framework\views.py", line 509, in dispatch
    response = self.handle_exception(exc)
  File "C:\Python310\lib\site-packages\rest_framework\views.py", line 469, in handle_exception
    self.raise_uncaught_exception(exc)
  File "C:\Python310\lib\site-packages\rest_framework\views.py", line 480, in raise_uncaught_exception
    raise exc
  File "C:\Python310\lib\site-packages\rest_framework\views.py", line 506, in dispatch
    response = handler(request, *args, **kwargs)
  File "C:\Users\Lenovo\Documents\projects\InventoryManagementSystem\inventorymanagementsystem\apps\orders\orderviews.py", line 38, in create
    new_order = self.order_service.create(validated_data, order_products)
  File "C:\Python310\lib\contextlib.py", line 79, in inner
    return func(*args, **kwds)
  File "C:\Users\Lenovo\Documents\projects\InventoryManagementSystem\inventorymanagementsystem\apps\orders\service.py", line 43, in create
    invoice = self.create_invoice(new_order)
  File "C:\Users\Lenovo\Documents\projects\InventoryManagementSystem\inventorymanagementsystem\apps\orders\service.py", line 91, in create_invoice
    amount = amount + (product_price * product_quantity)
UnboundLocalError: local variable 'amount' referenced before assignment
ERROR 2022-04-18 11:40:16,946 basehttp 12192 10892 "POST /orders/ HTTP/1.1" 500 145
INFO 2022-04-18 11:44:41,300 autoreload 12192 14044 C:\Users\Lenovo\Documents\projects\InventoryManagementSystem\inventorymanagementsystem\apps\orders\service.py changed, reloading.
INFO 2022-04-18 11:44:42,500 autoreload 2956 2920 Watching for file changes with StatReloader
INFO 2022-04-18 11:44:53,868 autoreload 2956 2920 C:\Users\Lenovo\Documents\projects\InventoryManagementSystem\inventorymanagementsystem\apps\orders\service.py changed, reloading.
INFO 2022-04-18 11:44:54,730 autoreload 10792 12544 Watching for file changes with StatReloader
ERROR 2022-04-18 11:45:00,019 log 10792 5288 Internal Server Error: /orders/
Traceback (most recent call last):
  File "C:\Python310\lib\site-packages\django\core\handlers\exception.py", line 55, in inner
    response = get_response(request)
  File "C:\Python310\lib\site-packages\django\core\handlers\base.py", line 197, in _get_response
    response = wrapped_callback(request, *callback_args, **callback_kwargs)
  File "C:\Python310\lib\site-packages\django\views\decorators\csrf.py", line 54, in wrapped_view
    return view_func(*args, **kwargs)
  File "C:\Python310\lib\site-packages\rest_framework\viewsets.py", line 125, in view
    return self.dispatch(request, *args, **kwargs)
  File "C:\Python310\lib\site-packages\rest_framework\views.py", line 509, in dispatch
    response = self.handle_exception(exc)
  File "C:\Python310\lib\site-packages\rest_framework\views.py", line 469, in handle_exception
    self.raise_uncaught_exception(exc)
  File "C:\Python310\lib\site-packages\rest_framework\views.py", line 480, in raise_uncaught_exception
    raise exc
  File "C:\Python310\lib\site-packages\rest_framework\views.py", line 506, in dispatch
    response = handler(request, *args, **kwargs)
  File "C:\Users\Lenovo\Documents\projects\InventoryManagementSystem\inventorymanagementsystem\apps\orders\orderviews.py", line 38, in create
    new_order = self.order_service.create(validated_data, order_products)
  File "C:\Python310\lib\contextlib.py", line 79, in inner
    return func(*args, **kwds)
  File "C:\Users\Lenovo\Documents\projects\InventoryManagementSystem\inventorymanagementsystem\apps\orders\service.py", line 43, in create
    invoice = self.create_invoice(new_order)
  File "C:\Users\Lenovo\Documents\projects\InventoryManagementSystem\inventorymanagementsystem\apps\orders\service.py", line 92, in create_invoice
    amount = amount + (product_price * product_quantity)
NameError: name 'amount' is not defined
ERROR 2022-04-18 11:45:00,025 basehttp 10792 5288 "POST /orders/ HTTP/1.1" 500 145
INFO 2022-04-18 11:48:39,594 autoreload 10792 12544 C:\Users\Lenovo\Documents\projects\InventoryManagementSystem\inventorymanagementsystem\apps\orders\service.py changed, reloading.
INFO 2022-04-18 11:48:40,587 autoreload 10232 5672 Watching for file changes with StatReloader
ERROR 2022-04-18 11:48:45,330 log 10232 13712 Internal Server Error: /orders/
Traceback (most recent call last):
  File "C:\Python310\lib\site-packages\django\db\backends\utils.py", line 89, in _execute
    return self.cursor.execute(sql, params)
  File "C:\Python310\lib\site-packages\django\db\backends\mysql\base.py", line 75, in execute
    return self.cursor.execute(query, args)
  File "C:\Python310\lib\site-packages\MySQLdb\cursors.py", line 206, in execute
    res = self._query(query)
  File "C:\Python310\lib\site-packages\MySQLdb\cursors.py", line 319, in _query
    db.query(q)
  File "C:\Python310\lib\site-packages\MySQLdb\connections.py", line 254, in query
    _mysql.connection.query(self, query)
MySQLdb._exceptions.DataError: (1264, "Out of range value for column 'amount' at row 1")

The above exception was the direct cause of the following exception:

Traceback (most recent call last):
  File "C:\Python310\lib\site-packages\django\core\handlers\exception.py", line 55, in inner
    response = get_response(request)
  File "C:\Python310\lib\site-packages\django\core\handlers\base.py", line 197, in _get_response
    response = wrapped_callback(request, *callback_args, **callback_kwargs)
  File "C:\Python310\lib\site-packages\django\views\decorators\csrf.py", line 54, in wrapped_view
    return view_func(*args, **kwargs)
  File "C:\Python310\lib\site-packages\rest_framework\viewsets.py", line 125, in view
    return self.dispatch(request, *args, **kwargs)
  File "C:\Python310\lib\site-packages\rest_framework\views.py", line 509, in dispatch
    response = self.handle_exception(exc)
  File "C:\Python310\lib\site-packages\rest_framework\views.py", line 469, in handle_exception
    self.raise_uncaught_exception(exc)
  File "C:\Python310\lib\site-packages\rest_framework\views.py", line 480, in raise_uncaught_exception
    raise exc
  File "C:\Python310\lib\site-packages\rest_framework\views.py", line 506, in dispatch
    response = handler(request, *args, **kwargs)
  File "C:\Users\Lenovo\Documents\projects\InventoryManagementSystem\inventorymanagementsystem\apps\orders\orderviews.py", line 38, in create
    new_order = self.order_service.create(validated_data, order_products)
  File "C:\Python310\lib\contextlib.py", line 79, in inner
    return func(*args, **kwds)
  File "C:\Users\Lenovo\Documents\projects\InventoryManagementSystem\inventorymanagementsystem\apps\orders\service.py", line 43, in create
    invoice = self.create_invoice(new_order)
  File "C:\Users\Lenovo\Documents\projects\InventoryManagementSystem\inventorymanagementsystem\apps\orders\service.py", line 96, in create_invoice
    invoice = Invoice.objects.create(amount=amount, created_date=created_date,
  File "C:\Python310\lib\site-packages\django\db\models\manager.py", line 85, in manager_method
    return getattr(self.get_queryset(), name)(*args, **kwargs)
  File "C:\Python310\lib\site-packages\django\db\models\query.py", line 514, in create
    obj.save(force_insert=True, using=self.db)
  File "C:\Python310\lib\site-packages\django\db\models\base.py", line 806, in save
    self.save_base(
  File "C:\Python310\lib\site-packages\django\db\models\base.py", line 857, in save_base
    updated = self._save_table(
  File "C:\Python310\lib\site-packages\django\db\models\base.py", line 1000, in _save_table
    results = self._do_insert(
  File "C:\Python310\lib\site-packages\django\db\models\base.py", line 1041, in _do_insert
    return manager._insert(
  File "C:\Python310\lib\site-packages\django\db\models\manager.py", line 85, in manager_method
    return getattr(self.get_queryset(), name)(*args, **kwargs)
  File "C:\Python310\lib\site-packages\django\db\models\query.py", line 1434, in _insert
    return query.get_compiler(using=using).execute_sql(returning_fields)
  File "C:\Python310\lib\site-packages\django\db\models\sql\compiler.py", line 1621, in execute_sql
    cursor.execute(sql, params)
  File "C:\Python310\lib\site-packages\django\db\backends\utils.py", line 67, in execute
    return self._execute_with_wrappers(
  File "C:\Python310\lib\site-packages\django\db\backends\utils.py", line 80, in _execute_with_wrappers
    return executor(sql, params, many, context)
  File "C:\Python310\lib\site-packages\django\db\backends\utils.py", line 84, in _execute
    with self.db.wrap_database_errors:
  File "C:\Python310\lib\site-packages\django\db\utils.py", line 91, in __exit__
    raise dj_exc_value.with_traceback(traceback) from exc_value
  File "C:\Python310\lib\site-packages\django\db\backends\utils.py", line 89, in _execute
    return self.cursor.execute(sql, params)
  File "C:\Python310\lib\site-packages\django\db\backends\mysql\base.py", line 75, in execute
    return self.cursor.execute(query, args)
  File "C:\Python310\lib\site-packages\MySQLdb\cursors.py", line 206, in execute
    res = self._query(query)
  File "C:\Python310\lib\site-packages\MySQLdb\cursors.py", line 319, in _query
    db.query(q)
  File "C:\Python310\lib\site-packages\MySQLdb\connections.py", line 254, in query
    _mysql.connection.query(self, query)
django.db.utils.DataError: (1264, "Out of range value for column 'amount' at row 1")
ERROR 2022-04-18 11:48:45,339 basehttp 10232 13712 "POST /orders/ HTTP/1.1" 500 145
INFO 2022-04-18 11:50:50,347 autoreload 10232 5672 C:\Users\Lenovo\Documents\projects\InventoryManagementSystem\inventorymanagementsystem\apps\payments\models.py changed, reloading.
INFO 2022-04-18 11:50:51,368 autoreload 14184 9848 Watching for file changes with StatReloader
INFO 2022-04-18 11:51:31,657 autoreload 12408 12968 Watching for file changes with StatReloader
INFO 2022-04-18 11:51:39,003 basehttp 12408 5732 "POST /orders/ HTTP/1.1" 200 164
INFO 2022-04-18 11:57:11,666 autoreload 12408 12968 C:\Users\Lenovo\Documents\projects\InventoryManagementSystem\inventorymanagementsystem\apps\orders\service.py changed, reloading.
INFO 2022-04-18 11:57:12,696 autoreload 6496 3304 Watching for file changes with StatReloader
INFO 2022-04-18 11:57:52,640 autoreload 6496 3304 C:\Users\Lenovo\Documents\projects\InventoryManagementSystem\inventorymanagementsystem\apps\orders\service.py changed, reloading.
INFO 2022-04-18 11:57:53,621 autoreload 11428 10100 Watching for file changes with StatReloader
INFO 2022-04-18 12:23:12,287 autoreload 11428 10100 C:\Users\Lenovo\Documents\projects\InventoryManagementSystem\inventorymanagementsystem\inventorymanagementsystem\urls.py changed, reloading.
INFO 2022-04-18 12:23:13,336 autoreload 3296 1404 Watching for file changes with StatReloader
INFO 2022-04-18 12:24:40,269 autoreload 3296 1404 C:\Users\Lenovo\Documents\projects\InventoryManagementSystem\inventorymanagementsystem\inventorymanagementsystem\urls.py changed, reloading.
INFO 2022-04-18 12:24:41,239 autoreload 4100 1748 Watching for file changes with StatReloader
INFO 2022-04-18 12:25:05,933 autoreload 4100 1748 C:\Users\Lenovo\Documents\projects\InventoryManagementSystem\inventorymanagementsystem\inventorymanagementsystem\urls.py changed, reloading.
INFO 2022-04-18 12:25:07,075 autoreload 3436 2740 Watching for file changes with StatReloader
INFO 2022-04-18 12:26:18,088 autoreload 3436 2740 C:\Users\Lenovo\Documents\projects\InventoryManagementSystem\inventorymanagementsystem\apps\payments\urls.py changed, reloading.
INFO 2022-04-18 12:26:19,301 autoreload 11284 6572 Watching for file changes with StatReloader
INFO 2022-04-18 12:26:41,955 autoreload 11284 6572 C:\Users\Lenovo\Documents\projects\InventoryManagementSystem\inventorymanagementsystem\apps\payments\urls.py changed, reloading.
INFO 2022-04-18 12:26:42,990 autoreload 7292 8496 Watching for file changes with StatReloader
INFO 2022-04-18 12:27:20,228 autoreload 7292 8496 C:\Users\Lenovo\Documents\projects\InventoryManagementSystem\inventorymanagementsystem\apps\payments\views.py changed, reloading.
INFO 2022-04-18 12:27:21,172 autoreload 3340 2400 Watching for file changes with StatReloader
INFO 2022-04-18 12:27:57,031 basehttp 3340 5180 "GET /invoice/ HTTP/1.1" 200 127
INFO 2022-04-18 12:28:05,088 basehttp 3340 5180 "GET /invoice/1/ HTTP/1.1" 200 125
INFO 2022-04-18 12:29:17,847 autoreload 3340 2400 C:\Users\Lenovo\Documents\projects\InventoryManagementSystem\inventorymanagementsystem\inventorymanagementsystem\urls.py changed, reloading.
INFO 2022-04-18 12:29:19,221 autoreload 2228 9648 Watching for file changes with StatReloader
INFO 2022-04-18 12:31:37,182 autoreload 2228 9648 C:\Users\Lenovo\Documents\projects\InventoryManagementSystem\inventorymanagementsystem\apps\payments\views.py changed, reloading.
INFO 2022-04-18 12:31:38,376 autoreload 12832 8800 Watching for file changes with StatReloader
INFO 2022-04-18 12:34:19,838 autoreload 12832 8800 C:\Users\Lenovo\Documents\projects\InventoryManagementSystem\inventorymanagementsystem\apps\payments\views.py changed, reloading.
INFO 2022-04-18 12:34:21,209 autoreload 13484 13216 Watching for file changes with StatReloader
INFO 2022-04-18 12:36:20,119 autoreload 13484 13216 C:\Users\Lenovo\Documents\projects\InventoryManagementSystem\inventorymanagementsystem\apps\payments\views.py changed, reloading.
INFO 2022-04-18 12:36:21,177 autoreload 10440 8284 Watching for file changes with StatReloader
INFO 2022-04-18 12:36:29,869 autoreload 10440 8284 C:\Users\Lenovo\Documents\projects\InventoryManagementSystem\inventorymanagementsystem\apps\payments\views.py changed, reloading.
INFO 2022-04-18 12:36:30,809 autoreload 13420 976 Watching for file changes with StatReloader
WARNING 2022-04-18 12:36:59,638 log 13420 9280 Bad Request: /invoice/
WARNING 2022-04-18 12:36:59,638 basehttp 13420 9280 "POST /invoice/ HTTP/1.1" 400 128
INFO 2022-04-18 12:38:03,525 basehttp 13420 9280 "POST /invoice/ HTTP/1.1" 200 108
INFO 2022-04-18 12:39:28,470 autoreload 13420 976 C:\Users\Lenovo\Documents\projects\InventoryManagementSystem\inventorymanagementsystem\apps\payments\views.py changed, reloading.
INFO 2022-04-18 12:39:29,744 autoreload 12012 1972 Watching for file changes with StatReloader
INFO 2022-04-18 12:43:30,661 autoreload 12012 1972 C:\Users\Lenovo\Documents\projects\InventoryManagementSystem\inventorymanagementsystem\apps\payments\serializers.py changed, reloading.
INFO 2022-04-18 12:43:31,999 autoreload 11160 13172 Watching for file changes with StatReloader
INFO 2022-04-18 12:45:10,947 autoreload 11160 13172 C:\Users\Lenovo\Documents\projects\InventoryManagementSystem\inventorymanagementsystem\apps\payments\serializers.py changed, reloading.
INFO 2022-04-18 12:45:12,331 autoreload 1464 6168 Watching for file changes with StatReloader
INFO 2022-04-18 12:47:48,711 autoreload 1464 6168 C:\Users\Lenovo\Documents\projects\InventoryManagementSystem\inventorymanagementsystem\apps\payments\models.py changed, reloading.
INFO 2022-04-18 12:47:50,390 autoreload 3364 8892 Watching for file changes with StatReloader
INFO 2022-04-18 12:49:18,844 autoreload 3364 8892 C:\Users\Lenovo\Documents\projects\InventoryManagementSystem\inventorymanagementsystem\apps\payments\models.py changed, reloading.
INFO 2022-04-18 12:49:20,236 autoreload 416 9712 Watching for file changes with StatReloader
INFO 2022-04-18 12:49:33,910 autoreload 416 9712 C:\Users\Lenovo\Documents\projects\InventoryManagementSystem\inventorymanagementsystem\apps\payments\serializers.py changed, reloading.
INFO 2022-04-18 12:49:35,142 autoreload 6644 5968 Watching for file changes with StatReloader
INFO 2022-04-18 12:51:29,819 autoreload 6644 5968 C:\Users\Lenovo\Documents\projects\InventoryManagementSystem\inventorymanagementsystem\apps\payments\serializers.py changed, reloading.
INFO 2022-04-18 12:51:30,891 autoreload 12532 2624 Watching for file changes with StatReloader
INFO 2022-04-18 12:54:11,882 autoreload 12532 2624 C:\Users\Lenovo\Documents\projects\InventoryManagementSystem\inventorymanagementsystem\apps\payments\views.py changed, reloading.
INFO 2022-04-18 12:54:12,992 autoreload 5180 1080 Watching for file changes with StatReloader
INFO 2022-04-18 12:56:35,385 autoreload 5180 1080 C:\Users\Lenovo\Documents\projects\InventoryManagementSystem\inventorymanagementsystem\apps\payments\views.py changed, reloading.
INFO 2022-04-18 12:56:36,498 autoreload 12384 12264 Watching for file changes with StatReloader
INFO 2022-04-18 12:56:38,172 autoreload 12384 12264 C:\Users\Lenovo\Documents\projects\InventoryManagementSystem\inventorymanagementsystem\apps\payments\views.py changed, reloading.
INFO 2022-04-18 12:56:39,140 autoreload 11740 8856 Watching for file changes with StatReloader
INFO 2022-04-18 12:59:47,960 basehttp 11740 12736 "GET /invoice/ HTTP/1.1" 200 120
INFO 2022-04-18 13:00:20,602 basehttp 11740 12736 "GET /orders/ HTTP/1.1" 200 4261
ERROR 2022-04-18 13:01:20,670 log 11740 12736 Internal Server Error: /invoice/
Traceback (most recent call last):
  File "C:\Python310\lib\site-packages\django\core\handlers\exception.py", line 55, in inner
    response = get_response(request)
  File "C:\Python310\lib\site-packages\django\core\handlers\base.py", line 197, in _get_response
    response = wrapped_callback(request, *callback_args, **callback_kwargs)
  File "C:\Python310\lib\site-packages\django\views\decorators\csrf.py", line 54, in wrapped_view
    return view_func(*args, **kwargs)
  File "C:\Python310\lib\site-packages\rest_framework\viewsets.py", line 125, in view
    return self.dispatch(request, *args, **kwargs)
  File "C:\Python310\lib\site-packages\rest_framework\views.py", line 509, in dispatch
    response = self.handle_exception(exc)
  File "C:\Python310\lib\site-packages\rest_framework\views.py", line 469, in handle_exception
    self.raise_uncaught_exception(exc)
  File "C:\Python310\lib\site-packages\rest_framework\views.py", line 480, in raise_uncaught_exception
    raise exc
  File "C:\Python310\lib\site-packages\rest_framework\views.py", line 506, in dispatch
    response = handler(request, *args, **kwargs)
  File "C:\Users\Lenovo\Documents\projects\InventoryManagementSystem\inventorymanagementsystem\apps\payments\views.py", line 17, in create
    new_invoice = self.invoice_service.create(validated_data)
AttributeError: 'InvoiceView' object has no attribute 'invoice_service'
ERROR 2022-04-18 13:01:20,677 basehttp 11740 12736 "POST /invoice/ HTTP/1.1" 500 145
INFO 2022-04-18 13:02:20,256 autoreload 11740 8856 C:\Users\Lenovo\Documents\projects\InventoryManagementSystem\inventorymanagementsystem\apps\payments\views.py changed, reloading.
INFO 2022-04-18 13:02:21,676 autoreload 11548 2584 Watching for file changes with StatReloader
INFO 2022-04-18 13:03:23,022 autoreload 11548 2584 C:\Users\Lenovo\Documents\projects\InventoryManagementSystem\inventorymanagementsystem\apps\payments\service.py changed, reloading.
INFO 2022-04-18 13:03:24,100 autoreload 10492 9380 Watching for file changes with StatReloader
ERROR 2022-04-18 13:03:29,491 log 10492 13672 Internal Server Error: /invoice/
Traceback (most recent call last):
  File "C:\Python310\lib\site-packages\django\core\handlers\exception.py", line 55, in inner
    response = get_response(request)
  File "C:\Python310\lib\site-packages\django\core\handlers\base.py", line 197, in _get_response
    response = wrapped_callback(request, *callback_args, **callback_kwargs)
  File "C:\Python310\lib\site-packages\django\views\decorators\csrf.py", line 54, in wrapped_view
    return view_func(*args, **kwargs)
  File "C:\Python310\lib\site-packages\rest_framework\viewsets.py", line 125, in view
    return self.dispatch(request, *args, **kwargs)
  File "C:\Python310\lib\site-packages\rest_framework\views.py", line 509, in dispatch
    response = self.handle_exception(exc)
  File "C:\Python310\lib\site-packages\rest_framework\views.py", line 469, in handle_exception
    self.raise_uncaught_exception(exc)
  File "C:\Python310\lib\site-packages\rest_framework\views.py", line 480, in raise_uncaught_exception
    raise exc
  File "C:\Python310\lib\site-packages\rest_framework\views.py", line 506, in dispatch
    response = handler(request, *args, **kwargs)
  File "C:\Users\Lenovo\Documents\projects\InventoryManagementSystem\inventorymanagementsystem\apps\payments\views.py", line 20, in create
    serialized = OrderSerializer(new_invoice)
NameError: name 'OrderSerializer' is not defined
ERROR 2022-04-18 13:03:29,498 basehttp 10492 13672 "POST /invoice/ HTTP/1.1" 500 145
INFO 2022-04-18 13:05:13,194 autoreload 10492 9380 C:\Users\Lenovo\Documents\projects\InventoryManagementSystem\inventorymanagementsystem\apps\payments\service.py changed, reloading.
INFO 2022-04-18 13:05:14,359 autoreload 10220 676 Watching for file changes with StatReloader
INFO 2022-04-18 13:05:31,325 autoreload 10220 676 C:\Users\Lenovo\Documents\projects\InventoryManagementSystem\inventorymanagementsystem\apps\payments\service.py changed, reloading.
INFO 2022-04-18 13:05:32,440 autoreload 6680 1776 Watching for file changes with StatReloader
INFO 2022-04-18 13:05:44,169 autoreload 6680 1776 C:\Users\Lenovo\Documents\projects\InventoryManagementSystem\inventorymanagementsystem\apps\payments\service.py changed, reloading.
INFO 2022-04-18 13:05:45,250 autoreload 13600 13552 Watching for file changes with StatReloader
ERROR 2022-04-18 13:05:49,458 log 13600 13708 Internal Server Error: /invoice/
Traceback (most recent call last):
  File "C:\Python310\lib\site-packages\django\core\handlers\exception.py", line 55, in inner
    response = get_response(request)
  File "C:\Python310\lib\site-packages\django\core\handlers\base.py", line 197, in _get_response
    response = wrapped_callback(request, *callback_args, **callback_kwargs)
  File "C:\Python310\lib\site-packages\django\views\decorators\csrf.py", line 54, in wrapped_view
    return view_func(*args, **kwargs)
  File "C:\Python310\lib\site-packages\rest_framework\viewsets.py", line 125, in view
    return self.dispatch(request, *args, **kwargs)
  File "C:\Python310\lib\site-packages\rest_framework\views.py", line 509, in dispatch
    response = self.handle_exception(exc)
  File "C:\Python310\lib\site-packages\rest_framework\views.py", line 469, in handle_exception
    self.raise_uncaught_exception(exc)
  File "C:\Python310\lib\site-packages\rest_framework\views.py", line 480, in raise_uncaught_exception
    raise exc
  File "C:\Python310\lib\site-packages\rest_framework\views.py", line 506, in dispatch
    response = handler(request, *args, **kwargs)
  File "C:\Users\Lenovo\Documents\projects\InventoryManagementSystem\inventorymanagementsystem\apps\payments\views.py", line 20, in create
    serialized = OrderSerializer(new_invoice)
NameError: name 'OrderSerializer' is not defined
ERROR 2022-04-18 13:05:49,467 basehttp 13600 13708 "POST /invoice/ HTTP/1.1" 500 145
INFO 2022-04-18 13:07:02,449 autoreload 13600 13552 C:\Users\Lenovo\Documents\projects\InventoryManagementSystem\inventorymanagementsystem\apps\payments\service.py changed, reloading.
INFO 2022-04-18 13:07:03,378 autoreload 5772 656 Watching for file changes with StatReloader
INFO 2022-04-18 13:07:07,371 autoreload 5772 656 C:\Users\Lenovo\Documents\projects\InventoryManagementSystem\inventorymanagementsystem\apps\payments\service.py changed, reloading.
INFO 2022-04-18 13:07:08,419 autoreload 2972 10748 Watching for file changes with StatReloader
WARNING 2022-04-18 13:07:12,238 log 2972 5584 Bad Request: /invoice/
WARNING 2022-04-18 13:07:12,238 basehttp 2972 5584 "POST /invoice/ HTTP/1.1" 400 64
ERROR 2022-04-18 13:07:58,882 log 2972 5584 Internal Server Error: /invoice/
Traceback (most recent call last):
  File "C:\Python310\lib\site-packages\django\core\handlers\exception.py", line 55, in inner
    response = get_response(request)
  File "C:\Python310\lib\site-packages\django\core\handlers\base.py", line 197, in _get_response
    response = wrapped_callback(request, *callback_args, **callback_kwargs)
  File "C:\Python310\lib\site-packages\django\views\decorators\csrf.py", line 54, in wrapped_view
    return view_func(*args, **kwargs)
  File "C:\Python310\lib\site-packages\rest_framework\viewsets.py", line 125, in view
    return self.dispatch(request, *args, **kwargs)
  File "C:\Python310\lib\site-packages\rest_framework\views.py", line 509, in dispatch
    response = self.handle_exception(exc)
  File "C:\Python310\lib\site-packages\rest_framework\views.py", line 469, in handle_exception
    self.raise_uncaught_exception(exc)
  File "C:\Python310\lib\site-packages\rest_framework\views.py", line 480, in raise_uncaught_exception
    raise exc
  File "C:\Python310\lib\site-packages\rest_framework\views.py", line 506, in dispatch
    response = handler(request, *args, **kwargs)
  File "C:\Users\Lenovo\Documents\projects\InventoryManagementSystem\inventorymanagementsystem\apps\payments\views.py", line 20, in create
    serialized = OrderSerializer(new_invoice)
NameError: name 'OrderSerializer' is not defined
ERROR 2022-04-18 13:07:58,884 basehttp 2972 5584 "POST /invoice/ HTTP/1.1" 500 145
INFO 2022-04-18 13:08:36,151 autoreload 2972 10748 C:\Users\Lenovo\Documents\projects\InventoryManagementSystem\inventorymanagementsystem\apps\payments\service.py changed, reloading.
INFO 2022-04-18 13:08:37,179 autoreload 4636 13492 Watching for file changes with StatReloader
INFO 2022-04-18 13:09:03,248 autoreload 4636 13492 C:\Users\Lenovo\Documents\projects\InventoryManagementSystem\inventorymanagementsystem\apps\payments\service.py changed, reloading.
INFO 2022-04-18 13:09:04,436 autoreload 780 2712 Watching for file changes with StatReloader
INFO 2022-04-18 13:09:40,153 autoreload 780 2712 C:\Users\Lenovo\Documents\projects\InventoryManagementSystem\inventorymanagementsystem\apps\payments\service.py changed, reloading.
INFO 2022-04-18 13:09:41,215 autoreload 12968 512 Watching for file changes with StatReloader
WARNING 2022-04-18 13:09:56,204 log 12968 9684 Bad Request: /invoice/
WARNING 2022-04-18 13:09:56,205 basehttp 12968 9684 "POST /invoice/ HTTP/1.1" 400 64
ERROR 2022-04-18 13:10:21,631 log 12968 9684 Internal Server Error: /invoice/
Traceback (most recent call last):
  File "C:\Python310\lib\site-packages\django\core\handlers\exception.py", line 55, in inner
    response = get_response(request)
  File "C:\Python310\lib\site-packages\django\core\handlers\base.py", line 197, in _get_response
    response = wrapped_callback(request, *callback_args, **callback_kwargs)
  File "C:\Python310\lib\site-packages\django\views\decorators\csrf.py", line 54, in wrapped_view
    return view_func(*args, **kwargs)
  File "C:\Python310\lib\site-packages\rest_framework\viewsets.py", line 125, in view
    return self.dispatch(request, *args, **kwargs)
  File "C:\Python310\lib\site-packages\rest_framework\views.py", line 509, in dispatch
    response = self.handle_exception(exc)
  File "C:\Python310\lib\site-packages\rest_framework\views.py", line 469, in handle_exception
    self.raise_uncaught_exception(exc)
  File "C:\Python310\lib\site-packages\rest_framework\views.py", line 480, in raise_uncaught_exception
    raise exc
  File "C:\Python310\lib\site-packages\rest_framework\views.py", line 506, in dispatch
    response = handler(request, *args, **kwargs)
  File "C:\Users\Lenovo\Documents\projects\InventoryManagementSystem\inventorymanagementsystem\apps\payments\views.py", line 20, in create
    serialized = OrderSerializer(new_invoice)
NameError: name 'OrderSerializer' is not defined
ERROR 2022-04-18 13:10:21,635 basehttp 12968 9684 "POST /invoice/ HTTP/1.1" 500 145
INFO 2022-04-18 13:10:48,212 autoreload 12968 512 C:\Users\Lenovo\Documents\projects\InventoryManagementSystem\inventorymanagementsystem\apps\payments\service.py changed, reloading.
INFO 2022-04-18 13:10:49,739 autoreload 5540 7848 Watching for file changes with StatReloader
INFO 2022-04-18 13:11:19,009 autoreload 5540 7848 C:\Users\Lenovo\Documents\projects\InventoryManagementSystem\inventorymanagementsystem\apps\payments\service.py changed, reloading.
INFO 2022-04-18 13:11:20,478 autoreload 11296 14252 Watching for file changes with StatReloader
WARNING 2022-04-18 13:11:33,630 log 11296 11160 Bad Request: /invoice/
WARNING 2022-04-18 13:11:33,631 basehttp 11296 11160 "POST /invoice/ HTTP/1.1" 400 64
ERROR 2022-04-18 13:11:44,427 log 11296 11160 Internal Server Error: /invoice/
Traceback (most recent call last):
  File "C:\Python310\lib\site-packages\rest_framework\views.py", line 506, in dispatch
    response = handler(request, *args, **kwargs)
  File "C:\Users\Lenovo\Documents\projects\InventoryManagementSystem\inventorymanagementsystem\apps\payments\views.py", line 18, in create
    validated_data.is_valid(raise_exception=True)
  File "C:\Python310\lib\site-packages\rest_framework\serializers.py", line 235, in is_valid
    raise ValidationError(self.errors)
rest_framework.exceptions.ValidationError: {'order': [ErrorDetail(string='Invalid pk "250" - object does not exist.', code='does_not_exist')], 'status_code': 400}

During handling of the above exception, another exception occurred:

Traceback (most recent call last):
  File "C:\Python310\lib\site-packages\django\core\handlers\exception.py", line 55, in inner
    response = get_response(request)
  File "C:\Python310\lib\site-packages\django\core\handlers\base.py", line 197, in _get_response
    response = wrapped_callback(request, *callback_args, **callback_kwargs)
  File "C:\Python310\lib\site-packages\django\views\decorators\csrf.py", line 54, in wrapped_view
    return view_func(*args, **kwargs)
  File "C:\Python310\lib\site-packages\rest_framework\viewsets.py", line 125, in view
    return self.dispatch(request, *args, **kwargs)
  File "C:\Python310\lib\site-packages\rest_framework\views.py", line 509, in dispatch
    response = self.handle_exception(exc)
  File "C:\Python310\lib\site-packages\rest_framework\views.py", line 466, in handle_exception
    response = exception_handler(exc, context)
  File "C:\Users\Lenovo\Documents\projects\InventoryManagementSystem\inventorymanagementsystem\utils\exceptionhandler.py", line 14, in custom_exception_handler
    response.data['message'] = response.data['detail']
KeyError: 'detail'
ERROR 2022-04-18 13:11:44,438 basehttp 11296 11160 "POST /invoice/ HTTP/1.1" 500 145
INFO 2022-04-18 13:12:44,848 autoreload 11296 14252 C:\Users\Lenovo\Documents\projects\InventoryManagementSystem\inventorymanagementsystem\apps\payments\service.py changed, reloading.
INFO 2022-04-18 13:12:46,069 autoreload 11656 5300 Watching for file changes with StatReloader
INFO 2022-04-18 13:13:24,505 autoreload 11656 5300 C:\Users\Lenovo\Documents\projects\InventoryManagementSystem\inventorymanagementsystem\apps\payments\service.py changed, reloading.
INFO 2022-04-18 13:13:25,829 autoreload 10248 2908 Watching for file changes with StatReloader
INFO 2022-04-18 13:52:18,748 autoreload 10248 2908 C:\Users\Lenovo\Documents\projects\InventoryManagementSystem\inventorymanagementsystem\apps\payments\service.py changed, reloading.
INFO 2022-04-18 13:52:19,708 autoreload 5436 14980 Watching for file changes with StatReloader
INFO 2022-04-18 13:53:25,837 autoreload 5436 14980 C:\Users\Lenovo\Documents\projects\InventoryManagementSystem\inventorymanagementsystem\apps\payments\service.py changed, reloading.
INFO 2022-04-18 13:53:26,759 autoreload 12392 5348 Watching for file changes with StatReloader
INFO 2022-04-18 13:54:06,350 basehttp 12392 6440 "GET /orders/ HTTP/1.1" 200 4261
INFO 2022-04-18 13:56:48,782 autoreload 12392 5348 C:\Users\Lenovo\Documents\projects\InventoryManagementSystem\inventorymanagementsystem\apps\payments\service.py changed, reloading.
INFO 2022-04-18 13:56:49,579 autoreload 14704 12412 Watching for file changes with StatReloader
INFO 2022-04-18 13:56:52,156 autoreload 14704 12412 C:\Users\Lenovo\Documents\projects\InventoryManagementSystem\inventorymanagementsystem\apps\payments\service.py changed, reloading.
INFO 2022-04-18 13:56:53,148 autoreload 9296 15300 Watching for file changes with StatReloader
INFO 2022-04-18 13:57:12,766 basehttp 9296 12416 "GET /invoice/ HTTP/1.1" 200 120
ERROR 2022-04-18 13:57:29,370 log 9296 12416 Internal Server Error: /invoice/
Traceback (most recent call last):
  File "C:\Python310\lib\site-packages\django\core\handlers\exception.py", line 55, in inner
    response = get_response(request)
  File "C:\Python310\lib\site-packages\django\core\handlers\base.py", line 197, in _get_response
    response = wrapped_callback(request, *callback_args, **callback_kwargs)
  File "C:\Python310\lib\site-packages\django\views\decorators\csrf.py", line 54, in wrapped_view
    return view_func(*args, **kwargs)
  File "C:\Python310\lib\site-packages\rest_framework\viewsets.py", line 125, in view
    return self.dispatch(request, *args, **kwargs)
  File "C:\Python310\lib\site-packages\rest_framework\views.py", line 509, in dispatch
    response = self.handle_exception(exc)
  File "C:\Python310\lib\site-packages\rest_framework\views.py", line 469, in handle_exception
    self.raise_uncaught_exception(exc)
  File "C:\Python310\lib\site-packages\rest_framework\views.py", line 480, in raise_uncaught_exception
    raise exc
  File "C:\Python310\lib\site-packages\rest_framework\views.py", line 506, in dispatch
    response = handler(request, *args, **kwargs)
  File "C:\Users\Lenovo\Documents\projects\InventoryManagementSystem\inventorymanagementsystem\apps\payments\views.py", line 20, in create
    serialized = OrderSerializer(new_invoice)
NameError: name 'OrderSerializer' is not defined
ERROR 2022-04-18 13:57:29,372 basehttp 9296 12416 "POST /invoice/ HTTP/1.1" 500 145
INFO 2022-04-18 14:00:36,568 autoreload 9296 15300 C:\Users\Lenovo\Documents\projects\InventoryManagementSystem\inventorymanagementsystem\apps\payments\service.py changed, reloading.
INFO 2022-04-18 14:00:37,487 autoreload 11852 6448 Watching for file changes with StatReloader
INFO 2022-04-18 14:01:53,441 autoreload 11852 6448 C:\Users\Lenovo\Documents\projects\InventoryManagementSystem\inventorymanagementsystem\apps\payments\serializers.py changed, reloading.
INFO 2022-04-18 14:01:54,321 autoreload 15156 5964 Watching for file changes with StatReloader
INFO 2022-04-18 14:03:34,581 autoreload 15156 5964 C:\Users\Lenovo\Documents\projects\InventoryManagementSystem\inventorymanagementsystem\apps\payments\models.py changed, reloading.
INFO 2022-04-18 14:03:35,272 autoreload 12740 4104 Watching for file changes with StatReloader
INFO 2022-04-18 14:05:57,098 autoreload 12740 4104 C:\Users\Lenovo\Documents\projects\InventoryManagementSystem\inventorymanagementsystem\apps\orders\models.py changed, reloading.
INFO 2022-04-18 14:05:57,801 autoreload 13040 7748 Watching for file changes with StatReloader
INFO 2022-04-18 14:06:07,280 autoreload 13040 7748 C:\Users\Lenovo\Documents\projects\InventoryManagementSystem\inventorymanagementsystem\apps\orders\models.py changed, reloading.
INFO 2022-04-18 14:06:08,009 autoreload 14616 9724 Watching for file changes with StatReloader
INFO 2022-04-18 14:06:51,540 autoreload 14616 9724 C:\Users\Lenovo\Documents\projects\InventoryManagementSystem\inventorymanagementsystem\apps\payments\models.py changed, reloading.
INFO 2022-04-18 14:06:52,320 autoreload 2736 14464 Watching for file changes with StatReloader
INFO 2022-04-18 14:08:04,837 autoreload 2736 14464 C:\Users\Lenovo\Documents\projects\InventoryManagementSystem\inventorymanagementsystem\apps\payments\service.py changed, reloading.
INFO 2022-04-18 14:08:05,754 autoreload 11004 5824 Watching for file changes with StatReloader
INFO 2022-04-18 14:09:22,507 autoreload 11004 5824 C:\Users\Lenovo\Documents\projects\InventoryManagementSystem\inventorymanagementsystem\apps\payments\service.py changed, reloading.
INFO 2022-04-18 14:09:23,273 autoreload 12488 7440 Watching for file changes with StatReloader
INFO 2022-04-18 14:09:46,983 autoreload 12488 7440 C:\Users\Lenovo\Documents\projects\InventoryManagementSystem\inventorymanagementsystem\apps\payments\service.py changed, reloading.
INFO 2022-04-18 14:09:47,812 autoreload 15324 13536 Watching for file changes with StatReloader
INFO 2022-04-18 14:10:29,686 autoreload 15324 13536 C:\Users\Lenovo\Documents\projects\InventoryManagementSystem\inventorymanagementsystem\apps\payments\service.py changed, reloading.
INFO 2022-04-18 14:10:30,479 autoreload 5540 5300 Watching for file changes with StatReloader
INFO 2022-04-18 14:10:55,254 autoreload 5540 5300 C:\Users\Lenovo\Documents\projects\InventoryManagementSystem\inventorymanagementsystem\apps\payments\serializers.py changed, reloading.
INFO 2022-04-18 14:10:56,067 autoreload 14672 4172 Watching for file changes with StatReloader
INFO 2022-04-18 14:11:27,275 autoreload 14672 4172 C:\Users\Lenovo\Documents\projects\InventoryManagementSystem\inventorymanagementsystem\apps\payments\service.py changed, reloading.
INFO 2022-04-18 14:11:28,056 autoreload 9888 15000 Watching for file changes with StatReloader
INFO 2022-04-18 14:11:33,873 autoreload 9888 15000 C:\Users\Lenovo\Documents\projects\InventoryManagementSystem\inventorymanagementsystem\apps\payments\service.py changed, reloading.
INFO 2022-04-18 14:11:34,748 autoreload 6452 2972 Watching for file changes with StatReloader
INFO 2022-04-18 14:12:35,809 autoreload 6452 2972 C:\Users\Lenovo\Documents\projects\InventoryManagementSystem\inventorymanagementsystem\apps\payments\service.py changed, reloading.
INFO 2022-04-18 14:12:36,732 autoreload 15336 14776 Watching for file changes with StatReloader
INFO 2022-04-18 14:14:37,637 autoreload 15336 14776 C:\Users\Lenovo\Documents\projects\InventoryManagementSystem\inventorymanagementsystem\apps\payments\service.py changed, reloading.
INFO 2022-04-18 14:14:38,512 autoreload 6796 11244 Watching for file changes with StatReloader
INFO 2022-04-18 14:15:06,712 autoreload 6796 11244 C:\Users\Lenovo\Documents\projects\InventoryManagementSystem\inventorymanagementsystem\apps\payments\service.py changed, reloading.
INFO 2022-04-18 14:15:07,526 autoreload 12980 14216 Watching for file changes with StatReloader
