INFO 2022-04-18 10:54:10,318 autoreload 2484 10504 Watching for file changes with StatReloader
ERROR 2022-04-18 10:54:14,926 log 2484 7100 Internal Server Error: /orders/
Traceback (most recent call last):
  File "C:\Python310\lib\site-packages\django\core\handlers\exception.py", line 55, in inner
    response = get_response(request)
  File "C:\Python310\lib\site-packages\django\core\handlers\base.py", line 197, in _get_response
    response = wrapped_callback(request, *callback_args, **callback_kwargs)
  File "C:\Python310\lib\site-packages\django\views\decorators\csrf.py", line 54, in wrapped_view
    return view_func(*args, **kwargs)
  File "C:\Python310\lib\site-packages\rest_framework\viewsets.py", line 125, in view
    return self.dispatch(request, *args, **kwargs)
  File "C:\Python310\lib\site-packages\rest_framework\views.py", line 509, in dispatch
    response = self.handle_exception(exc)
  File "C:\Python310\lib\site-packages\rest_framework\views.py", line 469, in handle_exception
    self.raise_uncaught_exception(exc)
  File "C:\Python310\lib\site-packages\rest_framework\views.py", line 480, in raise_uncaught_exception
    raise exc
  File "C:\Python310\lib\site-packages\rest_framework\views.py", line 506, in dispatch
    response = handler(request, *args, **kwargs)
  File "C:\Users\Lenovo\Documents\projects\InventoryManagementSystem\inventorymanagementsystem\apps\orders\orderviews.py", line 38, in create
    new_order = self.order_service.create(validated_data, order_products)
  File "C:\Python310\lib\contextlib.py", line 79, in inner
    return func(*args, **kwds)
  File "C:\Users\Lenovo\Documents\projects\InventoryManagementSystem\inventorymanagementsystem\apps\orders\service.py", line 42, in create
    invoice = self.create_invoice(order_product_data)
  File "C:\Users\Lenovo\Documents\projects\InventoryManagementSystem\inventorymanagementsystem\apps\orders\service.py", line 83, in create_invoice
    print(order_product.data)
AttributeError: 'OrderProduct' object has no attribute 'data'
ERROR 2022-04-18 10:54:14,932 basehttp 2484 7100 "POST /orders/ HTTP/1.1" 500 145
INFO 2022-04-18 10:54:37,818 autoreload 2484 10504 C:\Users\Lenovo\Documents\projects\InventoryManagementSystem\inventorymanagementsystem\apps\orders\service.py changed, reloading.
INFO 2022-04-18 10:54:38,717 autoreload 12936 13496 Watching for file changes with StatReloader
INFO 2022-04-18 10:54:42,244 basehttp 12936 5408 "POST /orders/ HTTP/1.1" 200 164
INFO 2022-04-18 10:55:10,736 autoreload 12936 13496 C:\Users\Lenovo\Documents\projects\InventoryManagementSystem\inventorymanagementsystem\apps\orders\service.py changed, reloading.
INFO 2022-04-18 10:55:11,718 autoreload 7016 1160 Watching for file changes with StatReloader
INFO 2022-04-18 10:55:15,581 basehttp 7016 7340 "POST /orders/ HTTP/1.1" 200 164
INFO 2022-04-18 10:55:26,810 autoreload 7016 1160 C:\Users\Lenovo\Documents\projects\InventoryManagementSystem\inventorymanagementsystem\apps\orders\service.py changed, reloading.
INFO 2022-04-18 10:55:27,813 autoreload 5760 1880 Watching for file changes with StatReloader
INFO 2022-04-18 10:55:33,281 basehttp 5760 10516 "POST /orders/ HTTP/1.1" 200 164
INFO 2022-04-18 10:55:44,127 autoreload 5760 1880 C:\Users\Lenovo\Documents\projects\InventoryManagementSystem\inventorymanagementsystem\apps\orders\service.py changed, reloading.
INFO 2022-04-18 10:55:45,433 autoreload 11440 12836 Watching for file changes with StatReloader
ERROR 2022-04-18 10:55:46,422 log 11440 3424 Internal Server Error: /orders/
Traceback (most recent call last):
  File "C:\Python310\lib\site-packages\django\core\handlers\exception.py", line 55, in inner
    response = get_response(request)
  File "C:\Python310\lib\site-packages\django\core\handlers\base.py", line 197, in _get_response
    response = wrapped_callback(request, *callback_args, **callback_kwargs)
  File "C:\Python310\lib\site-packages\django\views\decorators\csrf.py", line 54, in wrapped_view
    return view_func(*args, **kwargs)
  File "C:\Python310\lib\site-packages\rest_framework\viewsets.py", line 125, in view
    return self.dispatch(request, *args, **kwargs)
  File "C:\Python310\lib\site-packages\rest_framework\views.py", line 509, in dispatch
    response = self.handle_exception(exc)
  File "C:\Python310\lib\site-packages\rest_framework\views.py", line 469, in handle_exception
    self.raise_uncaught_exception(exc)
  File "C:\Python310\lib\site-packages\rest_framework\views.py", line 480, in raise_uncaught_exception
    raise exc
  File "C:\Python310\lib\site-packages\rest_framework\views.py", line 506, in dispatch
    response = handler(request, *args, **kwargs)
  File "C:\Users\Lenovo\Documents\projects\InventoryManagementSystem\inventorymanagementsystem\apps\orders\orderviews.py", line 38, in create
    new_order = self.order_service.create(validated_data, order_products)
  File "C:\Python310\lib\contextlib.py", line 79, in inner
    return func(*args, **kwds)
  File "C:\Users\Lenovo\Documents\projects\InventoryManagementSystem\inventorymanagementsystem\apps\orders\service.py", line 42, in create
    invoice = self.create_invoice(new_order)
  File "C:\Users\Lenovo\Documents\projects\InventoryManagementSystem\inventorymanagementsystem\apps\orders\service.py", line 83, in create_invoice
    print(new_order.data)
AttributeError: 'Order' object has no attribute 'data'
ERROR 2022-04-18 10:55:46,428 basehttp 11440 3424 "POST /orders/ HTTP/1.1" 500 145
INFO 2022-04-18 10:55:50,606 autoreload 11440 12836 C:\Users\Lenovo\Documents\projects\InventoryManagementSystem\inventorymanagementsystem\apps\orders\service.py changed, reloading.
INFO 2022-04-18 10:55:51,559 autoreload 5148 784 Watching for file changes with StatReloader
INFO 2022-04-18 10:55:51,923 basehttp 5148 11248 "POST /orders/ HTTP/1.1" 200 164
INFO 2022-04-18 10:56:04,454 autoreload 5148 784 C:\Users\Lenovo\Documents\projects\InventoryManagementSystem\inventorymanagementsystem\apps\orders\service.py changed, reloading.
INFO 2022-04-18 10:56:05,621 autoreload 5784 3324 Watching for file changes with StatReloader
ERROR 2022-04-18 10:56:08,279 log 5784 12432 Internal Server Error: /orders/
Traceback (most recent call last):
  File "C:\Python310\lib\site-packages\django\core\handlers\exception.py", line 55, in inner
    response = get_response(request)
  File "C:\Python310\lib\site-packages\django\core\handlers\base.py", line 197, in _get_response
    response = wrapped_callback(request, *callback_args, **callback_kwargs)
  File "C:\Python310\lib\site-packages\django\views\decorators\csrf.py", line 54, in wrapped_view
    return view_func(*args, **kwargs)
  File "C:\Python310\lib\site-packages\rest_framework\viewsets.py", line 125, in view
    return self.dispatch(request, *args, **kwargs)
  File "C:\Python310\lib\site-packages\rest_framework\views.py", line 509, in dispatch
    response = self.handle_exception(exc)
  File "C:\Python310\lib\site-packages\rest_framework\views.py", line 469, in handle_exception
    self.raise_uncaught_exception(exc)
  File "C:\Python310\lib\site-packages\rest_framework\views.py", line 480, in raise_uncaught_exception
    raise exc
  File "C:\Python310\lib\site-packages\rest_framework\views.py", line 506, in dispatch
    response = handler(request, *args, **kwargs)
  File "C:\Users\Lenovo\Documents\projects\InventoryManagementSystem\inventorymanagementsystem\apps\orders\orderviews.py", line 38, in create
    new_order = self.order_service.create(validated_data, order_products)
  File "C:\Python310\lib\contextlib.py", line 79, in inner
    return func(*args, **kwds)
  File "C:\Users\Lenovo\Documents\projects\InventoryManagementSystem\inventorymanagementsystem\apps\orders\service.py", line 42, in create
    invoice = self.create_invoice(new_order)
  File "C:\Users\Lenovo\Documents\projects\InventoryManagementSystem\inventorymanagementsystem\apps\orders\service.py", line 83, in create_invoice
    print(new_order.objects.all())
  File "C:\Python310\lib\site-packages\django\db\models\manager.py", line 186, in __get__
    raise AttributeError(
AttributeError: Manager isn't accessible via Order instances
ERROR 2022-04-18 10:56:08,307 basehttp 5784 12432 "POST /orders/ HTTP/1.1" 500 145
INFO 2022-04-18 10:57:23,056 autoreload 5784 3324 C:\Users\Lenovo\Documents\projects\InventoryManagementSystem\inventorymanagementsystem\apps\orders\service.py changed, reloading.
INFO 2022-04-18 10:57:24,056 autoreload 652 8720 Watching for file changes with StatReloader
INFO 2022-04-18 10:57:26,773 basehttp 652 4716 "POST /orders/ HTTP/1.1" 200 164
INFO 2022-04-18 10:57:44,243 autoreload 652 8720 C:\Users\Lenovo\Documents\projects\InventoryManagementSystem\inventorymanagementsystem\apps\orders\service.py changed, reloading.
INFO 2022-04-18 10:57:45,374 autoreload 11656 4664 Watching for file changes with StatReloader
ERROR 2022-04-18 10:57:46,064 log 11656 6100 Internal Server Error: /orders/
Traceback (most recent call last):
  File "C:\Python310\lib\site-packages\django\core\handlers\exception.py", line 55, in inner
    response = get_response(request)
  File "C:\Python310\lib\site-packages\django\core\handlers\base.py", line 197, in _get_response
    response = wrapped_callback(request, *callback_args, **callback_kwargs)
  File "C:\Python310\lib\site-packages\django\views\decorators\csrf.py", line 54, in wrapped_view
    return view_func(*args, **kwargs)
  File "C:\Python310\lib\site-packages\rest_framework\viewsets.py", line 125, in view
    return self.dispatch(request, *args, **kwargs)
  File "C:\Python310\lib\site-packages\rest_framework\views.py", line 509, in dispatch
    response = self.handle_exception(exc)
  File "C:\Python310\lib\site-packages\rest_framework\views.py", line 469, in handle_exception
    self.raise_uncaught_exception(exc)
  File "C:\Python310\lib\site-packages\rest_framework\views.py", line 480, in raise_uncaught_exception
    raise exc
  File "C:\Python310\lib\site-packages\rest_framework\views.py", line 506, in dispatch
    response = handler(request, *args, **kwargs)
  File "C:\Users\Lenovo\Documents\projects\InventoryManagementSystem\inventorymanagementsystem\apps\orders\orderviews.py", line 38, in create
    new_order = self.order_service.create(validated_data, order_products)
  File "C:\Python310\lib\contextlib.py", line 79, in inner
    return func(*args, **kwds)
  File "C:\Users\Lenovo\Documents\projects\InventoryManagementSystem\inventorymanagementsystem\apps\orders\service.py", line 42, in create
    invoice = self.create_invoice(new_order)
  File "C:\Users\Lenovo\Documents\projects\InventoryManagementSystem\inventorymanagementsystem\apps\orders\service.py", line 84, in create_invoice
    print(order_serializer.data['order_products'])
KeyError: 'order_products'
ERROR 2022-04-18 10:57:46,065 basehttp 11656 6100 "POST /orders/ HTTP/1.1" 500 145
INFO 2022-04-18 10:57:58,065 autoreload 11656 4664 C:\Users\Lenovo\Documents\projects\InventoryManagementSystem\inventorymanagementsystem\apps\orders\service.py changed, reloading.
INFO 2022-04-18 10:57:59,183 autoreload 6888 8060 Watching for file changes with StatReloader
INFO 2022-04-18 10:58:05,657 basehttp 6888 11956 "POST /orders/ HTTP/1.1" 200 164
INFO 2022-04-18 10:58:22,471 autoreload 6888 8060 C:\Users\Lenovo\Documents\projects\InventoryManagementSystem\inventorymanagementsystem\apps\orders\service.py changed, reloading.
INFO 2022-04-18 10:58:23,642 autoreload 11492 7056 Watching for file changes with StatReloader
INFO 2022-04-18 10:58:24,741 basehttp 11492 8432 "POST /orders/ HTTP/1.1" 200 164
INFO 2022-04-18 10:59:03,530 autoreload 11492 7056 C:\Users\Lenovo\Documents\projects\InventoryManagementSystem\inventorymanagementsystem\apps\orders\service.py changed, reloading.
INFO 2022-04-18 10:59:04,759 autoreload 3536 9168 Watching for file changes with StatReloader
ERROR 2022-04-18 10:59:05,530 log 3536 5052 Internal Server Error: /orders/
Traceback (most recent call last):
  File "C:\Python310\lib\site-packages\django\core\handlers\exception.py", line 55, in inner
    response = get_response(request)
  File "C:\Python310\lib\site-packages\django\core\handlers\base.py", line 197, in _get_response
    response = wrapped_callback(request, *callback_args, **callback_kwargs)
  File "C:\Python310\lib\site-packages\django\views\decorators\csrf.py", line 54, in wrapped_view
    return view_func(*args, **kwargs)
  File "C:\Python310\lib\site-packages\rest_framework\viewsets.py", line 125, in view
    return self.dispatch(request, *args, **kwargs)
  File "C:\Python310\lib\site-packages\rest_framework\views.py", line 509, in dispatch
    response = self.handle_exception(exc)
  File "C:\Python310\lib\site-packages\rest_framework\views.py", line 469, in handle_exception
    self.raise_uncaught_exception(exc)
  File "C:\Python310\lib\site-packages\rest_framework\views.py", line 480, in raise_uncaught_exception
    raise exc
  File "C:\Python310\lib\site-packages\rest_framework\views.py", line 506, in dispatch
    response = handler(request, *args, **kwargs)
  File "C:\Users\Lenovo\Documents\projects\InventoryManagementSystem\inventorymanagementsystem\apps\orders\orderviews.py", line 38, in create
    new_order = self.order_service.create(validated_data, order_products)
  File "C:\Python310\lib\contextlib.py", line 79, in inner
    return func(*args, **kwds)
  File "C:\Users\Lenovo\Documents\projects\InventoryManagementSystem\inventorymanagementsystem\apps\orders\service.py", line 42, in create
    invoice = self.create_invoice(new_order)
  File "C:\Users\Lenovo\Documents\projects\InventoryManagementSystem\inventorymanagementsystem\apps\orders\service.py", line 84, in create_invoice
    print(order_serializer.data['orderproducts']['product'])
TypeError: list indices must be integers or slices, not str
ERROR 2022-04-18 10:59:05,533 basehttp 3536 5052 "POST /orders/ HTTP/1.1" 500 145
INFO 2022-04-18 10:59:40,777 autoreload 3536 9168 C:\Users\Lenovo\Documents\projects\InventoryManagementSystem\inventorymanagementsystem\apps\orders\service.py changed, reloading.
INFO 2022-04-18 10:59:41,813 autoreload 768 13916 Watching for file changes with StatReloader
INFO 2022-04-18 10:59:43,981 basehttp 768 12252 "POST /orders/ HTTP/1.1" 200 164
INFO 2022-04-18 11:00:08,401 autoreload 768 13916 C:\Users\Lenovo\Documents\projects\InventoryManagementSystem\inventorymanagementsystem\apps\orders\service.py changed, reloading.
INFO 2022-04-18 11:00:09,551 autoreload 12904 1464 Watching for file changes with StatReloader
INFO 2022-04-18 11:00:09,954 basehttp 12904 8768 "POST /orders/ HTTP/1.1" 200 164
INFO 2022-04-18 11:00:27,575 autoreload 12904 1464 C:\Users\Lenovo\Documents\projects\InventoryManagementSystem\inventorymanagementsystem\apps\orders\service.py changed, reloading.
INFO 2022-04-18 11:00:28,633 autoreload 7708 3528 Watching for file changes with StatReloader
INFO 2022-04-18 11:04:21,000 autoreload 7708 3528 C:\Users\Lenovo\Documents\projects\InventoryManagementSystem\inventorymanagementsystem\apps\orders\service.py changed, reloading.
INFO 2022-04-18 11:04:21,925 autoreload 11752 108 Watching for file changes with StatReloader
ERROR 2022-04-18 11:04:27,065 log 11752 7824 Internal Server Error: /orders/
Traceback (most recent call last):
  File "C:\Python310\lib\site-packages\django\core\handlers\exception.py", line 55, in inner
    response = get_response(request)
  File "C:\Python310\lib\site-packages\django\core\handlers\base.py", line 197, in _get_response
    response = wrapped_callback(request, *callback_args, **callback_kwargs)
  File "C:\Python310\lib\site-packages\django\views\decorators\csrf.py", line 54, in wrapped_view
    return view_func(*args, **kwargs)
  File "C:\Python310\lib\site-packages\rest_framework\viewsets.py", line 125, in view
    return self.dispatch(request, *args, **kwargs)
  File "C:\Python310\lib\site-packages\rest_framework\views.py", line 509, in dispatch
    response = self.handle_exception(exc)
  File "C:\Python310\lib\site-packages\rest_framework\views.py", line 469, in handle_exception
    self.raise_uncaught_exception(exc)
  File "C:\Python310\lib\site-packages\rest_framework\views.py", line 480, in raise_uncaught_exception
    raise exc
  File "C:\Python310\lib\site-packages\rest_framework\views.py", line 506, in dispatch
    response = handler(request, *args, **kwargs)
  File "C:\Users\Lenovo\Documents\projects\InventoryManagementSystem\inventorymanagementsystem\apps\orders\orderviews.py", line 38, in create
    new_order = self.order_service.create(validated_data, order_products)
  File "C:\Python310\lib\contextlib.py", line 79, in inner
    return func(*args, **kwds)
  File "C:\Users\Lenovo\Documents\projects\InventoryManagementSystem\inventorymanagementsystem\apps\orders\service.py", line 42, in create
    invoice = self.create_invoice(new_order)
  File "C:\Users\Lenovo\Documents\projects\InventoryManagementSystem\inventorymanagementsystem\apps\orders\service.py", line 87, in create_invoice
    product = products.get(id=order['product'])
NameError: name 'order' is not defined
ERROR 2022-04-18 11:04:27,078 basehttp 11752 7824 "POST /orders/ HTTP/1.1" 500 145
INFO 2022-04-18 11:04:58,535 autoreload 11752 108 C:\Users\Lenovo\Documents\projects\InventoryManagementSystem\inventorymanagementsystem\apps\orders\service.py changed, reloading.
INFO 2022-04-18 11:04:59,800 autoreload 13152 9600 Watching for file changes with StatReloader
INFO 2022-04-18 11:05:01,975 basehttp 13152 524 "POST /orders/ HTTP/1.1" 200 164
INFO 2022-04-18 11:06:03,586 autoreload 13152 9600 C:\Users\Lenovo\Documents\projects\InventoryManagementSystem\inventorymanagementsystem\apps\orders\service.py changed, reloading.
INFO 2022-04-18 11:06:04,443 autoreload 3184 7896 Watching for file changes with StatReloader
INFO 2022-04-18 11:08:19,440 autoreload 3184 7896 C:\Users\Lenovo\Documents\projects\InventoryManagementSystem\inventorymanagementsystem\apps\orders\service.py changed, reloading.
INFO 2022-04-18 11:08:20,331 autoreload 12816 11288 Watching for file changes with StatReloader
INFO 2022-04-18 11:08:25,302 autoreload 12816 11288 C:\Users\Lenovo\Documents\projects\InventoryManagementSystem\inventorymanagementsystem\apps\orders\service.py changed, reloading.
INFO 2022-04-18 11:08:26,499 autoreload 13900 1956 Watching for file changes with StatReloader
ERROR 2022-04-18 11:08:28,132 log 13900 2772 Internal Server Error: /orders/
Traceback (most recent call last):
  File "C:\Python310\lib\site-packages\django\core\handlers\exception.py", line 55, in inner
    response = get_response(request)
  File "C:\Python310\lib\site-packages\django\core\handlers\base.py", line 197, in _get_response
    response = wrapped_callback(request, *callback_args, **callback_kwargs)
  File "C:\Python310\lib\site-packages\django\views\decorators\csrf.py", line 54, in wrapped_view
    return view_func(*args, **kwargs)
  File "C:\Python310\lib\site-packages\rest_framework\viewsets.py", line 125, in view
    return self.dispatch(request, *args, **kwargs)
  File "C:\Python310\lib\site-packages\rest_framework\views.py", line 509, in dispatch
    response = self.handle_exception(exc)
  File "C:\Python310\lib\site-packages\rest_framework\views.py", line 469, in handle_exception
    self.raise_uncaught_exception(exc)
  File "C:\Python310\lib\site-packages\rest_framework\views.py", line 480, in raise_uncaught_exception
    raise exc
  File "C:\Python310\lib\site-packages\rest_framework\views.py", line 506, in dispatch
    response = handler(request, *args, **kwargs)
  File "C:\Users\Lenovo\Documents\projects\InventoryManagementSystem\inventorymanagementsystem\apps\orders\orderviews.py", line 38, in create
    new_order = self.order_service.create(validated_data, order_products)
  File "C:\Python310\lib\contextlib.py", line 79, in inner
    return func(*args, **kwds)
  File "C:\Users\Lenovo\Documents\projects\InventoryManagementSystem\inventorymanagementsystem\apps\orders\service.py", line 43, in create
    invoice = self.create_invoice(new_order)
  File "C:\Users\Lenovo\Documents\projects\InventoryManagementSystem\inventorymanagementsystem\apps\orders\service.py", line 94, in create_invoice
    payment_deadline = created_date + 15
TypeError: unsupported operand type(s) for +: 'builtin_function_or_method' and 'int'
ERROR 2022-04-18 11:08:28,139 basehttp 13900 2772 "POST /orders/ HTTP/1.1" 500 145
INFO 2022-04-18 11:26:22,303 autoreload 13900 1956 C:\Users\Lenovo\Documents\projects\InventoryManagementSystem\inventorymanagementsystem\apps\orders\service.py changed, reloading.
INFO 2022-04-18 11:26:23,224 autoreload 7572 6424 Watching for file changes with StatReloader
INFO 2022-04-18 11:26:31,234 autoreload 7572 6424 C:\Users\Lenovo\Documents\projects\InventoryManagementSystem\inventorymanagementsystem\apps\orders\service.py changed, reloading.
INFO 2022-04-18 11:26:32,324 autoreload 10416 13220 Watching for file changes with StatReloader
INFO 2022-04-18 11:26:39,448 autoreload 10416 13220 C:\Users\Lenovo\Documents\projects\InventoryManagementSystem\inventorymanagementsystem\apps\orders\service.py changed, reloading.
INFO 2022-04-18 11:26:40,303 autoreload 12168 7208 Watching for file changes with StatReloader
ERROR 2022-04-18 11:26:44,565 log 12168 11896 Internal Server Error: /orders/
Traceback (most recent call last):
  File "C:\Python310\lib\site-packages\django\core\handlers\exception.py", line 55, in inner
    response = get_response(request)
  File "C:\Python310\lib\site-packages\django\core\handlers\base.py", line 197, in _get_response
    response = wrapped_callback(request, *callback_args, **callback_kwargs)
  File "C:\Python310\lib\site-packages\django\views\decorators\csrf.py", line 54, in wrapped_view
    return view_func(*args, **kwargs)
  File "C:\Python310\lib\site-packages\rest_framework\viewsets.py", line 125, in view
    return self.dispatch(request, *args, **kwargs)
  File "C:\Python310\lib\site-packages\rest_framework\views.py", line 509, in dispatch
    response = self.handle_exception(exc)
  File "C:\Python310\lib\site-packages\rest_framework\views.py", line 469, in handle_exception
    self.raise_uncaught_exception(exc)
  File "C:\Python310\lib\site-packages\rest_framework\views.py", line 480, in raise_uncaught_exception
    raise exc
  File "C:\Python310\lib\site-packages\rest_framework\views.py", line 506, in dispatch
    response = handler(request, *args, **kwargs)
  File "C:\Users\Lenovo\Documents\projects\InventoryManagementSystem\inventorymanagementsystem\apps\orders\orderviews.py", line 38, in create
    new_order = self.order_service.create(validated_data, order_products)
  File "C:\Python310\lib\contextlib.py", line 79, in inner
    return func(*args, **kwds)
  File "C:\Users\Lenovo\Documents\projects\InventoryManagementSystem\inventorymanagementsystem\apps\orders\service.py", line 43, in create
    invoice = self.create_invoice(new_order)
  File "C:\Users\Lenovo\Documents\projects\InventoryManagementSystem\inventorymanagementsystem\apps\orders\service.py", line 94, in create_invoice
    payment_deadline = created_date + datetime.timedelta(days=15)
TypeError: unsupported operand type(s) for +: 'builtin_function_or_method' and 'datetime.timedelta'
ERROR 2022-04-18 11:26:44,576 basehttp 12168 11896 "POST /orders/ HTTP/1.1" 500 145
INFO 2022-04-18 11:27:30,637 autoreload 12168 7208 C:\Users\Lenovo\Documents\projects\InventoryManagementSystem\inventorymanagementsystem\apps\orders\service.py changed, reloading.
INFO 2022-04-18 11:27:31,483 autoreload 11708 10204 Watching for file changes with StatReloader
ERROR 2022-04-18 11:27:33,949 log 11708 2744 Internal Server Error: /orders/
Traceback (most recent call last):
  File "C:\Python310\lib\site-packages\django\core\handlers\exception.py", line 55, in inner
    response = get_response(request)
  File "C:\Python310\lib\site-packages\django\core\handlers\base.py", line 197, in _get_response
    response = wrapped_callback(request, *callback_args, **callback_kwargs)
  File "C:\Python310\lib\site-packages\django\views\decorators\csrf.py", line 54, in wrapped_view
    return view_func(*args, **kwargs)
  File "C:\Python310\lib\site-packages\rest_framework\viewsets.py", line 125, in view
    return self.dispatch(request, *args, **kwargs)
  File "C:\Python310\lib\site-packages\rest_framework\views.py", line 509, in dispatch
    response = self.handle_exception(exc)
  File "C:\Python310\lib\site-packages\rest_framework\views.py", line 469, in handle_exception
    self.raise_uncaught_exception(exc)
  File "C:\Python310\lib\site-packages\rest_framework\views.py", line 480, in raise_uncaught_exception
    raise exc
  File "C:\Python310\lib\site-packages\rest_framework\views.py", line 506, in dispatch
    response = handler(request, *args, **kwargs)
  File "C:\Users\Lenovo\Documents\projects\InventoryManagementSystem\inventorymanagementsystem\apps\orders\orderviews.py", line 38, in create
    new_order = self.order_service.create(validated_data, order_products)
  File "C:\Python310\lib\contextlib.py", line 79, in inner
    return func(*args, **kwds)
  File "C:\Users\Lenovo\Documents\projects\InventoryManagementSystem\inventorymanagementsystem\apps\orders\service.py", line 43, in create
    invoice = self.create_invoice(new_order)
  File "C:\Users\Lenovo\Documents\projects\InventoryManagementSystem\inventorymanagementsystem\apps\orders\service.py", line 94, in create_invoice
    payment_deadline = created_date.date() + datetime.timedelta(days=15)
AttributeError: 'builtin_function_or_method' object has no attribute 'date'
ERROR 2022-04-18 11:27:33,952 basehttp 11708 2744 "POST /orders/ HTTP/1.1" 500 145
ERROR 2022-04-18 11:27:36,843 log 11708 2744 Internal Server Error: /orders/
Traceback (most recent call last):
  File "C:\Python310\lib\site-packages\django\core\handlers\exception.py", line 55, in inner
    response = get_response(request)
  File "C:\Python310\lib\site-packages\django\core\handlers\base.py", line 197, in _get_response
    response = wrapped_callback(request, *callback_args, **callback_kwargs)
  File "C:\Python310\lib\site-packages\django\views\decorators\csrf.py", line 54, in wrapped_view
    return view_func(*args, **kwargs)
  File "C:\Python310\lib\site-packages\rest_framework\viewsets.py", line 125, in view
    return self.dispatch(request, *args, **kwargs)
  File "C:\Python310\lib\site-packages\rest_framework\views.py", line 509, in dispatch
    response = self.handle_exception(exc)
  File "C:\Python310\lib\site-packages\rest_framework\views.py", line 469, in handle_exception
    self.raise_uncaught_exception(exc)
  File "C:\Python310\lib\site-packages\rest_framework\views.py", line 480, in raise_uncaught_exception
    raise exc
  File "C:\Python310\lib\site-packages\rest_framework\views.py", line 506, in dispatch
    response = handler(request, *args, **kwargs)
  File "C:\Users\Lenovo\Documents\projects\InventoryManagementSystem\inventorymanagementsystem\apps\orders\orderviews.py", line 38, in create
    new_order = self.order_service.create(validated_data, order_products)
  File "C:\Python310\lib\contextlib.py", line 79, in inner
    return func(*args, **kwds)
  File "C:\Users\Lenovo\Documents\projects\InventoryManagementSystem\inventorymanagementsystem\apps\orders\service.py", line 43, in create
    invoice = self.create_invoice(new_order)
  File "C:\Users\Lenovo\Documents\projects\InventoryManagementSystem\inventorymanagementsystem\apps\orders\service.py", line 94, in create_invoice
    payment_deadline = created_date.date() + datetime.timedelta(days=15)
AttributeError: 'builtin_function_or_method' object has no attribute 'date'
ERROR 2022-04-18 11:27:36,845 basehttp 11708 2744 "POST /orders/ HTTP/1.1" 500 145
INFO 2022-04-18 11:28:34,681 autoreload 11708 10204 C:\Users\Lenovo\Documents\projects\InventoryManagementSystem\inventorymanagementsystem\apps\orders\service.py changed, reloading.
INFO 2022-04-18 11:28:35,813 autoreload 5752 11484 Watching for file changes with StatReloader
ERROR 2022-04-18 11:28:37,831 log 5752 7928 Internal Server Error: /orders/
Traceback (most recent call last):
  File "C:\Python310\lib\site-packages\django\core\handlers\exception.py", line 55, in inner
    response = get_response(request)
  File "C:\Python310\lib\site-packages\django\core\handlers\base.py", line 197, in _get_response
    response = wrapped_callback(request, *callback_args, **callback_kwargs)
  File "C:\Python310\lib\site-packages\django\views\decorators\csrf.py", line 54, in wrapped_view
    return view_func(*args, **kwargs)
  File "C:\Python310\lib\site-packages\rest_framework\viewsets.py", line 125, in view
    return self.dispatch(request, *args, **kwargs)
  File "C:\Python310\lib\site-packages\rest_framework\views.py", line 509, in dispatch
    response = self.handle_exception(exc)
  File "C:\Python310\lib\site-packages\rest_framework\views.py", line 469, in handle_exception
    self.raise_uncaught_exception(exc)
  File "C:\Python310\lib\site-packages\rest_framework\views.py", line 480, in raise_uncaught_exception
    raise exc
  File "C:\Python310\lib\site-packages\rest_framework\views.py", line 506, in dispatch
    response = handler(request, *args, **kwargs)
  File "C:\Users\Lenovo\Documents\projects\InventoryManagementSystem\inventorymanagementsystem\apps\orders\orderviews.py", line 38, in create
    new_order = self.order_service.create(validated_data, order_products)
  File "C:\Python310\lib\contextlib.py", line 79, in inner
    return func(*args, **kwds)
  File "C:\Users\Lenovo\Documents\projects\InventoryManagementSystem\inventorymanagementsystem\apps\orders\service.py", line 43, in create
    invoice = self.create_invoice(new_order)
  File "C:\Users\Lenovo\Documents\projects\InventoryManagementSystem\inventorymanagementsystem\apps\orders\service.py", line 94, in create_invoice
    payment_deadline = created_date + datetime.timedelta(days=15)
TypeError: unsupported operand type(s) for +: 'builtin_function_or_method' and 'datetime.timedelta'
ERROR 2022-04-18 11:28:37,834 basehttp 5752 7928 "POST /orders/ HTTP/1.1" 500 145
INFO 2022-04-18 11:29:16,119 autoreload 5752 11484 C:\Users\Lenovo\Documents\projects\InventoryManagementSystem\inventorymanagementsystem\apps\orders\service.py changed, reloading.
INFO 2022-04-18 11:29:17,054 autoreload 11424 5832 Watching for file changes with StatReloader
INFO 2022-04-18 11:29:26,523 autoreload 11424 5832 C:\Users\Lenovo\Documents\projects\InventoryManagementSystem\inventorymanagementsystem\apps\orders\service.py changed, reloading.
INFO 2022-04-18 11:29:27,494 autoreload 12828 1864 Watching for file changes with StatReloader
INFO 2022-04-18 11:29:31,328 autoreload 12828 1864 C:\Users\Lenovo\Documents\projects\InventoryManagementSystem\inventorymanagementsystem\apps\orders\service.py changed, reloading.
INFO 2022-04-18 11:29:32,410 autoreload 9980 10684 Watching for file changes with StatReloader
INFO 2022-04-18 11:30:02,559 autoreload 9980 10684 C:\Users\Lenovo\Documents\projects\InventoryManagementSystem\inventorymanagementsystem\apps\orders\service.py changed, reloading.
INFO 2022-04-18 11:30:03,446 autoreload 8056 6248 Watching for file changes with StatReloader
INFO 2022-04-18 11:30:13,946 autoreload 8056 6248 C:\Users\Lenovo\Documents\projects\InventoryManagementSystem\inventorymanagementsystem\apps\orders\service.py changed, reloading.
INFO 2022-04-18 11:30:14,987 autoreload 11008 1512 Watching for file changes with StatReloader
ERROR 2022-04-18 11:30:16,845 log 11008 5972 Internal Server Error: /orders/
Traceback (most recent call last):
  File "C:\Python310\lib\site-packages\django\core\handlers\exception.py", line 55, in inner
    response = get_response(request)
  File "C:\Python310\lib\site-packages\django\core\handlers\base.py", line 197, in _get_response
    response = wrapped_callback(request, *callback_args, **callback_kwargs)
  File "C:\Python310\lib\site-packages\django\views\decorators\csrf.py", line 54, in wrapped_view
    return view_func(*args, **kwargs)
  File "C:\Python310\lib\site-packages\rest_framework\viewsets.py", line 125, in view
    return self.dispatch(request, *args, **kwargs)
  File "C:\Python310\lib\site-packages\rest_framework\views.py", line 509, in dispatch
    response = self.handle_exception(exc)
  File "C:\Python310\lib\site-packages\rest_framework\views.py", line 469, in handle_exception
    self.raise_uncaught_exception(exc)
  File "C:\Python310\lib\site-packages\rest_framework\views.py", line 480, in raise_uncaught_exception
    raise exc
  File "C:\Python310\lib\site-packages\rest_framework\views.py", line 506, in dispatch
    response = handler(request, *args, **kwargs)
  File "C:\Users\Lenovo\Documents\projects\InventoryManagementSystem\inventorymanagementsystem\apps\orders\orderviews.py", line 38, in create
    new_order = self.order_service.create(validated_data, order_products)
  File "C:\Python310\lib\contextlib.py", line 79, in inner
    return func(*args, **kwds)
  File "C:\Users\Lenovo\Documents\projects\InventoryManagementSystem\inventorymanagementsystem\apps\orders\service.py", line 43, in create
    invoice = self.create_invoice(new_order)
  File "C:\Users\Lenovo\Documents\projects\InventoryManagementSystem\inventorymanagementsystem\apps\orders\service.py", line 93, in create_invoice
    created_date = date.today
NameError: name 'date' is not defined
ERROR 2022-04-18 11:30:16,851 basehttp 11008 5972 "POST /orders/ HTTP/1.1" 500 145
INFO 2022-04-18 11:30:44,345 autoreload 11008 1512 C:\Users\Lenovo\Documents\projects\InventoryManagementSystem\inventorymanagementsystem\apps\orders\service.py changed, reloading.
INFO 2022-04-18 11:30:45,255 autoreload 9260 3388 Watching for file changes with StatReloader
ERROR 2022-04-18 11:30:57,160 log 9260 1780 Internal Server Error: /orders/
Traceback (most recent call last):
  File "C:\Python310\lib\site-packages\django\core\handlers\exception.py", line 55, in inner
    response = get_response(request)
  File "C:\Python310\lib\site-packages\django\core\handlers\base.py", line 197, in _get_response
    response = wrapped_callback(request, *callback_args, **callback_kwargs)
  File "C:\Python310\lib\site-packages\django\views\decorators\csrf.py", line 54, in wrapped_view
    return view_func(*args, **kwargs)
  File "C:\Python310\lib\site-packages\rest_framework\viewsets.py", line 125, in view
    return self.dispatch(request, *args, **kwargs)
  File "C:\Python310\lib\site-packages\rest_framework\views.py", line 509, in dispatch
    response = self.handle_exception(exc)
  File "C:\Python310\lib\site-packages\rest_framework\views.py", line 469, in handle_exception
    self.raise_uncaught_exception(exc)
  File "C:\Python310\lib\site-packages\rest_framework\views.py", line 480, in raise_uncaught_exception
    raise exc
  File "C:\Python310\lib\site-packages\rest_framework\views.py", line 506, in dispatch
    response = handler(request, *args, **kwargs)
  File "C:\Users\Lenovo\Documents\projects\InventoryManagementSystem\inventorymanagementsystem\apps\orders\orderviews.py", line 38, in create
    new_order = self.order_service.create(validated_data, order_products)
  File "C:\Python310\lib\contextlib.py", line 79, in inner
    return func(*args, **kwds)
  File "C:\Users\Lenovo\Documents\projects\InventoryManagementSystem\inventorymanagementsystem\apps\orders\service.py", line 43, in create
    invoice = self.create_invoice(new_order)
  File "C:\Users\Lenovo\Documents\projects\InventoryManagementSystem\inventorymanagementsystem\apps\orders\service.py", line 93, in create_invoice
    created_date = datetime.date.today
AttributeError: 'method_descriptor' object has no attribute 'today'
ERROR 2022-04-18 11:30:57,164 basehttp 9260 1780 "POST /orders/ HTTP/1.1" 500 145
INFO 2022-04-18 11:31:45,270 autoreload 9260 3388 C:\Users\Lenovo\Documents\projects\InventoryManagementSystem\inventorymanagementsystem\apps\orders\service.py changed, reloading.
INFO 2022-04-18 11:31:46,252 autoreload 5916 3216 Watching for file changes with StatReloader
ERROR 2022-04-18 11:31:48,076 log 5916 6152 Internal Server Error: /orders/
Traceback (most recent call last):
  File "C:\Python310\lib\site-packages\django\core\handlers\exception.py", line 55, in inner
    response = get_response(request)
  File "C:\Python310\lib\site-packages\django\core\handlers\base.py", line 197, in _get_response
    response = wrapped_callback(request, *callback_args, **callback_kwargs)
  File "C:\Python310\lib\site-packages\django\views\decorators\csrf.py", line 54, in wrapped_view
    return view_func(*args, **kwargs)
  File "C:\Python310\lib\site-packages\rest_framework\viewsets.py", line 125, in view
    return self.dispatch(request, *args, **kwargs)
  File "C:\Python310\lib\site-packages\rest_framework\views.py", line 509, in dispatch
    response = self.handle_exception(exc)
  File "C:\Python310\lib\site-packages\rest_framework\views.py", line 469, in handle_exception
    self.raise_uncaught_exception(exc)
  File "C:\Python310\lib\site-packages\rest_framework\views.py", line 480, in raise_uncaught_exception
    raise exc
  File "C:\Python310\lib\site-packages\rest_framework\views.py", line 506, in dispatch
    response = handler(request, *args, **kwargs)
  File "C:\Users\Lenovo\Documents\projects\InventoryManagementSystem\inventorymanagementsystem\apps\orders\orderviews.py", line 38, in create
    new_order = self.order_service.create(validated_data, order_products)
  File "C:\Python310\lib\contextlib.py", line 79, in inner
    return func(*args, **kwds)
  File "C:\Users\Lenovo\Documents\projects\InventoryManagementSystem\inventorymanagementsystem\apps\orders\service.py", line 43, in create
    invoice = self.create_invoice(new_order)
  File "C:\Users\Lenovo\Documents\projects\InventoryManagementSystem\inventorymanagementsystem\apps\orders\service.py", line 95, in create_invoice
    payment_deadline = created_date + datetime.timedelta(days=15)
NameError: name 'datetime' is not defined
ERROR 2022-04-18 11:31:48,083 basehttp 5916 6152 "POST /orders/ HTTP/1.1" 500 145
INFO 2022-04-18 11:32:04,695 autoreload 5916 3216 C:\Users\Lenovo\Documents\projects\InventoryManagementSystem\inventorymanagementsystem\apps\orders\service.py changed, reloading.
INFO 2022-04-18 11:32:05,687 autoreload 4820 2532 Watching for file changes with StatReloader
INFO 2022-04-18 11:32:08,802 basehttp 4820 9548 "POST /orders/ HTTP/1.1" 200 164
INFO 2022-04-18 11:32:53,540 autoreload 4820 2532 C:\Users\Lenovo\Documents\projects\InventoryManagementSystem\inventorymanagementsystem\apps\orders\service.py changed, reloading.
INFO 2022-04-18 11:32:54,532 autoreload 2276 7868 Watching for file changes with StatReloader
INFO 2022-04-18 11:35:52,514 autoreload 9492 13428 Watching for file changes with StatReloader
INFO 2022-04-18 11:38:40,023 autoreload 9492 13428 C:\Users\Lenovo\Documents\projects\InventoryManagementSystem\inventorymanagementsystem\apps\orders\service.py changed, reloading.
INFO 2022-04-18 11:38:41,065 autoreload 1880 7312 Watching for file changes with StatReloader
INFO 2022-04-18 11:39:05,770 autoreload 1880 7312 C:\Users\Lenovo\Documents\projects\InventoryManagementSystem\inventorymanagementsystem\apps\orders\service.py changed, reloading.
INFO 2022-04-18 11:39:06,673 autoreload 7516 9648 Watching for file changes with StatReloader
ERROR 2022-04-18 11:39:32,302 log 7516 2900 Internal Server Error: /orders/
Traceback (most recent call last):
  File "C:\Python310\lib\site-packages\django\db\backends\utils.py", line 89, in _execute
    return self.cursor.execute(sql, params)
  File "C:\Python310\lib\site-packages\django\db\backends\mysql\base.py", line 75, in execute
    return self.cursor.execute(query, args)
  File "C:\Python310\lib\site-packages\MySQLdb\cursors.py", line 206, in execute
    res = self._query(query)
  File "C:\Python310\lib\site-packages\MySQLdb\cursors.py", line 319, in _query
    db.query(q)
  File "C:\Python310\lib\site-packages\MySQLdb\connections.py", line 254, in query
    _mysql.connection.query(self, query)
MySQLdb._exceptions.DataError: (1264, "Out of range value for column 'amount' at row 1")

The above exception was the direct cause of the following exception:

Traceback (most recent call last):
  File "C:\Python310\lib\site-packages\django\core\handlers\exception.py", line 55, in inner
    response = get_response(request)
  File "C:\Python310\lib\site-packages\django\core\handlers\base.py", line 197, in _get_response
    response = wrapped_callback(request, *callback_args, **callback_kwargs)
  File "C:\Python310\lib\site-packages\django\views\decorators\csrf.py", line 54, in wrapped_view
    return view_func(*args, **kwargs)
  File "C:\Python310\lib\site-packages\rest_framework\viewsets.py", line 125, in view
    return self.dispatch(request, *args, **kwargs)
  File "C:\Python310\lib\site-packages\rest_framework\views.py", line 509, in dispatch
    response = self.handle_exception(exc)
  File "C:\Python310\lib\site-packages\rest_framework\views.py", line 469, in handle_exception
    self.raise_uncaught_exception(exc)
  File "C:\Python310\lib\site-packages\rest_framework\views.py", line 480, in raise_uncaught_exception
    raise exc
  File "C:\Python310\lib\site-packages\rest_framework\views.py", line 506, in dispatch
    response = handler(request, *args, **kwargs)
  File "C:\Users\Lenovo\Documents\projects\InventoryManagementSystem\inventorymanagementsystem\apps\orders\orderviews.py", line 38, in create
    new_order = self.order_service.create(validated_data, order_products)
  File "C:\Python310\lib\contextlib.py", line 79, in inner
    return func(*args, **kwds)
  File "C:\Users\Lenovo\Documents\projects\InventoryManagementSystem\inventorymanagementsystem\apps\orders\service.py", line 43, in create
    invoice = self.create_invoice(new_order)
  File "C:\Users\Lenovo\Documents\projects\InventoryManagementSystem\inventorymanagementsystem\apps\orders\service.py", line 96, in create_invoice
    invoice = Invoice.objects.create(amount=amount, created_date=created_date,
  File "C:\Python310\lib\site-packages\django\db\models\manager.py", line 85, in manager_method
    return getattr(self.get_queryset(), name)(*args, **kwargs)
  File "C:\Python310\lib\site-packages\django\db\models\query.py", line 514, in create
    obj.save(force_insert=True, using=self.db)
  File "C:\Python310\lib\site-packages\django\db\models\base.py", line 806, in save
    self.save_base(
  File "C:\Python310\lib\site-packages\django\db\models\base.py", line 857, in save_base
    updated = self._save_table(
  File "C:\Python310\lib\site-packages\django\db\models\base.py", line 1000, in _save_table
    results = self._do_insert(
  File "C:\Python310\lib\site-packages\django\db\models\base.py", line 1041, in _do_insert
    return manager._insert(
  File "C:\Python310\lib\site-packages\django\db\models\manager.py", line 85, in manager_method
    return getattr(self.get_queryset(), name)(*args, **kwargs)
  File "C:\Python310\lib\site-packages\django\db\models\query.py", line 1434, in _insert
    return query.get_compiler(using=using).execute_sql(returning_fields)
  File "C:\Python310\lib\site-packages\django\db\models\sql\compiler.py", line 1621, in execute_sql
    cursor.execute(sql, params)
  File "C:\Python310\lib\site-packages\django\db\backends\utils.py", line 67, in execute
    return self._execute_with_wrappers(
  File "C:\Python310\lib\site-packages\django\db\backends\utils.py", line 80, in _execute_with_wrappers
    return executor(sql, params, many, context)
  File "C:\Python310\lib\site-packages\django\db\backends\utils.py", line 84, in _execute
    with self.db.wrap_database_errors:
  File "C:\Python310\lib\site-packages\django\db\utils.py", line 91, in __exit__
    raise dj_exc_value.with_traceback(traceback) from exc_value
  File "C:\Python310\lib\site-packages\django\db\backends\utils.py", line 89, in _execute
    return self.cursor.execute(sql, params)
  File "C:\Python310\lib\site-packages\django\db\backends\mysql\base.py", line 75, in execute
    return self.cursor.execute(query, args)
  File "C:\Python310\lib\site-packages\MySQLdb\cursors.py", line 206, in execute
    res = self._query(query)
  File "C:\Python310\lib\site-packages\MySQLdb\cursors.py", line 319, in _query
    db.query(q)
  File "C:\Python310\lib\site-packages\MySQLdb\connections.py", line 254, in query
    _mysql.connection.query(self, query)
django.db.utils.DataError: (1264, "Out of range value for column 'amount' at row 1")
ERROR 2022-04-18 11:39:32,439 basehttp 7516 2900 "POST /orders/ HTTP/1.1" 500 145
INFO 2022-04-18 11:40:10,681 autoreload 7516 9648 C:\Users\Lenovo\Documents\projects\InventoryManagementSystem\inventorymanagementsystem\apps\orders\service.py changed, reloading.
INFO 2022-04-18 11:40:11,584 autoreload 12192 14044 Watching for file changes with StatReloader
ERROR 2022-04-18 11:40:16,942 log 12192 10892 Internal Server Error: /orders/
Traceback (most recent call last):
  File "C:\Python310\lib\site-packages\django\core\handlers\exception.py", line 55, in inner
    response = get_response(request)
  File "C:\Python310\lib\site-packages\django\core\handlers\base.py", line 197, in _get_response
    response = wrapped_callback(request, *callback_args, **callback_kwargs)
  File "C:\Python310\lib\site-packages\django\views\decorators\csrf.py", line 54, in wrapped_view
    return view_func(*args, **kwargs)
  File "C:\Python310\lib\site-packages\rest_framework\viewsets.py", line 125, in view
    return self.dispatch(request, *args, **kwargs)
  File "C:\Python310\lib\site-packages\rest_framework\views.py", line 509, in dispatch
    response = self.handle_exception(exc)
  File "C:\Python310\lib\site-packages\rest_framework\views.py", line 469, in handle_exception
    self.raise_uncaught_exception(exc)
  File "C:\Python310\lib\site-packages\rest_framework\views.py", line 480, in raise_uncaught_exception
    raise exc
  File "C:\Python310\lib\site-packages\rest_framework\views.py", line 506, in dispatch
    response = handler(request, *args, **kwargs)
  File "C:\Users\Lenovo\Documents\projects\InventoryManagementSystem\inventorymanagementsystem\apps\orders\orderviews.py", line 38, in create
    new_order = self.order_service.create(validated_data, order_products)
  File "C:\Python310\lib\contextlib.py", line 79, in inner
    return func(*args, **kwds)
  File "C:\Users\Lenovo\Documents\projects\InventoryManagementSystem\inventorymanagementsystem\apps\orders\service.py", line 43, in create
    invoice = self.create_invoice(new_order)
  File "C:\Users\Lenovo\Documents\projects\InventoryManagementSystem\inventorymanagementsystem\apps\orders\service.py", line 91, in create_invoice
    amount = amount + (product_price * product_quantity)
UnboundLocalError: local variable 'amount' referenced before assignment
ERROR 2022-04-18 11:40:16,946 basehttp 12192 10892 "POST /orders/ HTTP/1.1" 500 145
INFO 2022-04-18 11:44:41,300 autoreload 12192 14044 C:\Users\Lenovo\Documents\projects\InventoryManagementSystem\inventorymanagementsystem\apps\orders\service.py changed, reloading.
INFO 2022-04-18 11:44:42,500 autoreload 2956 2920 Watching for file changes with StatReloader
INFO 2022-04-18 11:44:53,868 autoreload 2956 2920 C:\Users\Lenovo\Documents\projects\InventoryManagementSystem\inventorymanagementsystem\apps\orders\service.py changed, reloading.
INFO 2022-04-18 11:44:54,730 autoreload 10792 12544 Watching for file changes with StatReloader
ERROR 2022-04-18 11:45:00,019 log 10792 5288 Internal Server Error: /orders/
Traceback (most recent call last):
  File "C:\Python310\lib\site-packages\django\core\handlers\exception.py", line 55, in inner
    response = get_response(request)
  File "C:\Python310\lib\site-packages\django\core\handlers\base.py", line 197, in _get_response
    response = wrapped_callback(request, *callback_args, **callback_kwargs)
  File "C:\Python310\lib\site-packages\django\views\decorators\csrf.py", line 54, in wrapped_view
    return view_func(*args, **kwargs)
  File "C:\Python310\lib\site-packages\rest_framework\viewsets.py", line 125, in view
    return self.dispatch(request, *args, **kwargs)
  File "C:\Python310\lib\site-packages\rest_framework\views.py", line 509, in dispatch
    response = self.handle_exception(exc)
  File "C:\Python310\lib\site-packages\rest_framework\views.py", line 469, in handle_exception
    self.raise_uncaught_exception(exc)
  File "C:\Python310\lib\site-packages\rest_framework\views.py", line 480, in raise_uncaught_exception
    raise exc
  File "C:\Python310\lib\site-packages\rest_framework\views.py", line 506, in dispatch
    response = handler(request, *args, **kwargs)
  File "C:\Users\Lenovo\Documents\projects\InventoryManagementSystem\inventorymanagementsystem\apps\orders\orderviews.py", line 38, in create
    new_order = self.order_service.create(validated_data, order_products)
  File "C:\Python310\lib\contextlib.py", line 79, in inner
    return func(*args, **kwds)
  File "C:\Users\Lenovo\Documents\projects\InventoryManagementSystem\inventorymanagementsystem\apps\orders\service.py", line 43, in create
    invoice = self.create_invoice(new_order)
  File "C:\Users\Lenovo\Documents\projects\InventoryManagementSystem\inventorymanagementsystem\apps\orders\service.py", line 92, in create_invoice
    amount = amount + (product_price * product_quantity)
NameError: name 'amount' is not defined
ERROR 2022-04-18 11:45:00,025 basehttp 10792 5288 "POST /orders/ HTTP/1.1" 500 145
INFO 2022-04-18 11:48:39,594 autoreload 10792 12544 C:\Users\Lenovo\Documents\projects\InventoryManagementSystem\inventorymanagementsystem\apps\orders\service.py changed, reloading.
INFO 2022-04-18 11:48:40,587 autoreload 10232 5672 Watching for file changes with StatReloader
ERROR 2022-04-18 11:48:45,330 log 10232 13712 Internal Server Error: /orders/
Traceback (most recent call last):
  File "C:\Python310\lib\site-packages\django\db\backends\utils.py", line 89, in _execute
    return self.cursor.execute(sql, params)
  File "C:\Python310\lib\site-packages\django\db\backends\mysql\base.py", line 75, in execute
    return self.cursor.execute(query, args)
  File "C:\Python310\lib\site-packages\MySQLdb\cursors.py", line 206, in execute
    res = self._query(query)
  File "C:\Python310\lib\site-packages\MySQLdb\cursors.py", line 319, in _query
    db.query(q)
  File "C:\Python310\lib\site-packages\MySQLdb\connections.py", line 254, in query
    _mysql.connection.query(self, query)
MySQLdb._exceptions.DataError: (1264, "Out of range value for column 'amount' at row 1")

The above exception was the direct cause of the following exception:

Traceback (most recent call last):
  File "C:\Python310\lib\site-packages\django\core\handlers\exception.py", line 55, in inner
    response = get_response(request)
  File "C:\Python310\lib\site-packages\django\core\handlers\base.py", line 197, in _get_response
    response = wrapped_callback(request, *callback_args, **callback_kwargs)
  File "C:\Python310\lib\site-packages\django\views\decorators\csrf.py", line 54, in wrapped_view
    return view_func(*args, **kwargs)
  File "C:\Python310\lib\site-packages\rest_framework\viewsets.py", line 125, in view
    return self.dispatch(request, *args, **kwargs)
  File "C:\Python310\lib\site-packages\rest_framework\views.py", line 509, in dispatch
    response = self.handle_exception(exc)
  File "C:\Python310\lib\site-packages\rest_framework\views.py", line 469, in handle_exception
    self.raise_uncaught_exception(exc)
  File "C:\Python310\lib\site-packages\rest_framework\views.py", line 480, in raise_uncaught_exception
    raise exc
  File "C:\Python310\lib\site-packages\rest_framework\views.py", line 506, in dispatch
    response = handler(request, *args, **kwargs)
  File "C:\Users\Lenovo\Documents\projects\InventoryManagementSystem\inventorymanagementsystem\apps\orders\orderviews.py", line 38, in create
    new_order = self.order_service.create(validated_data, order_products)
  File "C:\Python310\lib\contextlib.py", line 79, in inner
    return func(*args, **kwds)
  File "C:\Users\Lenovo\Documents\projects\InventoryManagementSystem\inventorymanagementsystem\apps\orders\service.py", line 43, in create
    invoice = self.create_invoice(new_order)
  File "C:\Users\Lenovo\Documents\projects\InventoryManagementSystem\inventorymanagementsystem\apps\orders\service.py", line 96, in create_invoice
    invoice = Invoice.objects.create(amount=amount, created_date=created_date,
  File "C:\Python310\lib\site-packages\django\db\models\manager.py", line 85, in manager_method
    return getattr(self.get_queryset(), name)(*args, **kwargs)
  File "C:\Python310\lib\site-packages\django\db\models\query.py", line 514, in create
    obj.save(force_insert=True, using=self.db)
  File "C:\Python310\lib\site-packages\django\db\models\base.py", line 806, in save
    self.save_base(
  File "C:\Python310\lib\site-packages\django\db\models\base.py", line 857, in save_base
    updated = self._save_table(
  File "C:\Python310\lib\site-packages\django\db\models\base.py", line 1000, in _save_table
    results = self._do_insert(
  File "C:\Python310\lib\site-packages\django\db\models\base.py", line 1041, in _do_insert
    return manager._insert(
  File "C:\Python310\lib\site-packages\django\db\models\manager.py", line 85, in manager_method
    return getattr(self.get_queryset(), name)(*args, **kwargs)
  File "C:\Python310\lib\site-packages\django\db\models\query.py", line 1434, in _insert
    return query.get_compiler(using=using).execute_sql(returning_fields)
  File "C:\Python310\lib\site-packages\django\db\models\sql\compiler.py", line 1621, in execute_sql
    cursor.execute(sql, params)
  File "C:\Python310\lib\site-packages\django\db\backends\utils.py", line 67, in execute
    return self._execute_with_wrappers(
  File "C:\Python310\lib\site-packages\django\db\backends\utils.py", line 80, in _execute_with_wrappers
    return executor(sql, params, many, context)
  File "C:\Python310\lib\site-packages\django\db\backends\utils.py", line 84, in _execute
    with self.db.wrap_database_errors:
  File "C:\Python310\lib\site-packages\django\db\utils.py", line 91, in __exit__
    raise dj_exc_value.with_traceback(traceback) from exc_value
  File "C:\Python310\lib\site-packages\django\db\backends\utils.py", line 89, in _execute
    return self.cursor.execute(sql, params)
  File "C:\Python310\lib\site-packages\django\db\backends\mysql\base.py", line 75, in execute
    return self.cursor.execute(query, args)
  File "C:\Python310\lib\site-packages\MySQLdb\cursors.py", line 206, in execute
    res = self._query(query)
  File "C:\Python310\lib\site-packages\MySQLdb\cursors.py", line 319, in _query
    db.query(q)
  File "C:\Python310\lib\site-packages\MySQLdb\connections.py", line 254, in query
    _mysql.connection.query(self, query)
django.db.utils.DataError: (1264, "Out of range value for column 'amount' at row 1")
ERROR 2022-04-18 11:48:45,339 basehttp 10232 13712 "POST /orders/ HTTP/1.1" 500 145
INFO 2022-04-18 11:50:50,347 autoreload 10232 5672 C:\Users\Lenovo\Documents\projects\InventoryManagementSystem\inventorymanagementsystem\apps\payments\models.py changed, reloading.
INFO 2022-04-18 11:50:51,368 autoreload 14184 9848 Watching for file changes with StatReloader
INFO 2022-04-18 11:51:31,657 autoreload 12408 12968 Watching for file changes with StatReloader
INFO 2022-04-18 11:51:39,003 basehttp 12408 5732 "POST /orders/ HTTP/1.1" 200 164
INFO 2022-04-18 11:57:11,666 autoreload 12408 12968 C:\Users\Lenovo\Documents\projects\InventoryManagementSystem\inventorymanagementsystem\apps\orders\service.py changed, reloading.
INFO 2022-04-18 11:57:12,696 autoreload 6496 3304 Watching for file changes with StatReloader
INFO 2022-04-18 11:57:52,640 autoreload 6496 3304 C:\Users\Lenovo\Documents\projects\InventoryManagementSystem\inventorymanagementsystem\apps\orders\service.py changed, reloading.
INFO 2022-04-18 11:57:53,621 autoreload 11428 10100 Watching for file changes with StatReloader
INFO 2022-04-18 12:23:12,287 autoreload 11428 10100 C:\Users\Lenovo\Documents\projects\InventoryManagementSystem\inventorymanagementsystem\inventorymanagementsystem\urls.py changed, reloading.
INFO 2022-04-18 12:23:13,336 autoreload 3296 1404 Watching for file changes with StatReloader
INFO 2022-04-18 12:24:40,269 autoreload 3296 1404 C:\Users\Lenovo\Documents\projects\InventoryManagementSystem\inventorymanagementsystem\inventorymanagementsystem\urls.py changed, reloading.
INFO 2022-04-18 12:24:41,239 autoreload 4100 1748 Watching for file changes with StatReloader
INFO 2022-04-18 12:25:05,933 autoreload 4100 1748 C:\Users\Lenovo\Documents\projects\InventoryManagementSystem\inventorymanagementsystem\inventorymanagementsystem\urls.py changed, reloading.
INFO 2022-04-18 12:25:07,075 autoreload 3436 2740 Watching for file changes with StatReloader
INFO 2022-04-18 12:26:18,088 autoreload 3436 2740 C:\Users\Lenovo\Documents\projects\InventoryManagementSystem\inventorymanagementsystem\apps\payments\urls.py changed, reloading.
INFO 2022-04-18 12:26:19,301 autoreload 11284 6572 Watching for file changes with StatReloader
INFO 2022-04-18 12:26:41,955 autoreload 11284 6572 C:\Users\Lenovo\Documents\projects\InventoryManagementSystem\inventorymanagementsystem\apps\payments\urls.py changed, reloading.
INFO 2022-04-18 12:26:42,990 autoreload 7292 8496 Watching for file changes with StatReloader
INFO 2022-04-18 12:27:20,228 autoreload 7292 8496 C:\Users\Lenovo\Documents\projects\InventoryManagementSystem\inventorymanagementsystem\apps\payments\views.py changed, reloading.
INFO 2022-04-18 12:27:21,172 autoreload 3340 2400 Watching for file changes with StatReloader
INFO 2022-04-18 12:27:57,031 basehttp 3340 5180 "GET /invoice/ HTTP/1.1" 200 127
INFO 2022-04-18 12:28:05,088 basehttp 3340 5180 "GET /invoice/1/ HTTP/1.1" 200 125
INFO 2022-04-18 12:29:17,847 autoreload 3340 2400 C:\Users\Lenovo\Documents\projects\InventoryManagementSystem\inventorymanagementsystem\inventorymanagementsystem\urls.py changed, reloading.
INFO 2022-04-18 12:29:19,221 autoreload 2228 9648 Watching for file changes with StatReloader
